Workbook

Sheet README
A1: Aster & Vale Consumer Products Ltd — Month-End Management Accounts, Working Capital & 13-Week Cash Forecast
A3: Project 3 | Finance operations & management accounting flagship | V1 foundation
A5: Business case
A6: Aster & Vale Consumer Products Ltd is a fictional UK consumer-goods business. The September 2026 month-end requires Finance to close the ledger, post adjustments, reconcile balance-sheet accounts, produce management accounts, assess working capital and maintain a 13-week cash forecast.
A13: V1 workflow
A14: 1 | B14: Load opening TB and ERP-style GL extract
A15: 2 | B15: Map accounts to management-reporting lines
A16: 3 | B16: Post accruals, prepayments, depreciation and bad-debt adjustments
A17: 4 | B17: Produce adjusted trial balance with controls
A18: 5 | B18: Build management P&L and balance sheet
A19: 6 | B19: Reconcile bank, AR and AP
A20: 7 | B20: Calculate DSO, DPO, inventory days and CCC
A21: 8 | B21: Forecast 13 weeks of liquidity
A22: 9 | B22: Track month-end close tasks and unresolved items
A24: Portfolio integrity
A25: All transactions, balances, customer/supplier invoices and assumptions are synthetic. This is an independent portfolio case study and not work completed for a real employer.

Sheet Assumptions
A1: Close, Working Capital & Cash Forecast Assumptions
A5: Cash forecast assumptions
A6: Assumption | B6: Value | C6: Use | D6: Source
A7: Base Weekly Sales (£) | B7: 232000 | C7: Average forecast sales run-rate | D7: Synthetic management assumption
A8: Collection Rate | B8: 0.94 | C8: Share of sales converted to cash in near-term | D8: Synthetic management assumption
A9: Base Weekly COGS (£) | B9: 126000 | C9: Purchasing / supplier cash run-rate | D9: Synthetic management assumption
A10: Supplier Payment Factor | B10: 0.98 | C10: Cash payments vs weekly purchasing | D10: Synthetic management assumption
A11: Monthly Payroll Cash (£) | B11: 215000 | C11: Paid in weeks 4, 8 and 13 | D11: Synthetic management assumption
A12: Monthly Rent (£) | B12: 52000 | C12: Paid in weeks 1, 5, 9 and 13 | D12: Synthetic management assumption
A13: Weekly Other Opex (£) | B13: 27000 | C13: Software, marketing, utilities, travel | D13: Synthetic management assumption
A14: Minimum Cash Policy (£) | B14: 250000 | C14: Liquidity floor | D14: Synthetic treasury assumption
A15: Q4 Capex (£) | B15: 90000 | C15: Split across weeks 6 and 11 | D15: Synthetic capex plan
A16: Q4 Tax / Interest (£) | B16: 60000 | C16: Paid in week 10 | D16: Synthetic treasury assumption

Sheet Chart of Accounts
A1: Chart of Accounts
A3: Account Code | B3: Account Name | C3: Account Type | D3: Management Line | E3: Statement | F3: Normal Balance
A4: 1000 | B4: Bank | C4: Asset | D4: Cash | E4: BS | F4: Debit
A5: 1100 | B5: Trade Receivables | C5: Asset | D5: Trade Receivables | E5: BS | F5: Debit
A6: 1150 | B6: Allowance for Doubtful Debts | C6: Asset | D6: Allowance for Doubtful Debts | E6: BS | F6: Credit
A7: 1200 | B7: Inventory | C7: Asset | D7: Inventory | E7: BS | F7: Debit
A8: 1300 | B8: Prepayments | C8: Asset | D8: Prepayments | E8: BS | F8: Debit
A9: 1400 | B9: Property, Plant & Equipment | C9: Asset | D9: Property, Plant & Equipment | E9: BS | F9: Debit
A10: 1450 | B10: Accumulated Depreciation | C10: Asset | D10: Accumulated Depreciation | E10: BS | F10: Credit
A11: 2000 | B11: Trade Payables | C11: Liability | D11: Trade Payables | E11: BS | F11: Credit
A12: 2100 | B12: Accrued Expenses | C12: Liability | D12: Accrued Expenses | E12: BS | F12: Credit
A13: 2200 | B13: Payroll Liabilities | C13: Liability | D13: Payroll Liabilities | E13: BS | F13: Credit
A14: 2300 | B14: VAT / Tax Payable | C14: Liability | D14: Tax Payable | E14: BS | F14: Credit
... A30: 7000 | B30: Interest Expense | C30: Expense | D30: Interest | E30: PL | F30: Debit

Sheet Opening TB
A1: Opening Trial Balance — 31 Dec 2025
A3: Account Code | B3: Account Name | C3: Opening Balance (£) | D3: Debit (£) | E3: Credit (£) | F3: Source | G3: Control
A4: 1000 | B4: Bank | C4: 450000 | D4: 450000 | E4: 0 | F4: Synthetic opening balance | G4: =D4-E4-C4 -> 0
A5: 1100 | B5: Trade Receivables | C5: 800000 | D5: 800000 | E5: 0 | F5: Synthetic opening balance | G5: =D5-E5-C5 -> 0
A6: 1150 | B6: Allowance for Doubtful Debts | C6: -30000 | D6: 0 | E6: 30000 | F6: Synthetic opening balance | G6: =D6-E6-C6 -> 0
A7: 1200 | B7: Inventory | C7: 650000 | D7: 650000 | E7: 0 | F7: Synthetic opening balance | G7: =D7-E7-C7 -> 0
A8: 1300 | B8: Prepayments | C8: 90000 | D8: 90000 | E8: 0 | F8: Synthetic opening balance | G8: =D8-E8-C8 -> 0
A9: 1400 | B9: Property, Plant & Equipment | C9: 1200000 | D9: 1200000 | E9: 0 | F9: Synthetic opening balance | G9: =D9-E9-C9 -> 0
A10: 1450 | B10: Accumulated Depreciation | C10: -350000 | D10: 0 | E10: 350000 | F10: Synthetic opening balance | G10: =D10-E10-C10 -> 0
A11: 2000 | B11: Trade Payables | C11: -600000 | D11: 0 | E11: 600000 | F11: Synthetic opening balance | G11: =D11-E11-C11 -> 0
A12: 2100 | B12: Accrued Expenses | C12: -150000 | D12: 0 | E12: 150000 | F12: Synthetic opening balance | G12: =D12-E12-C12 -> 0
A13: 2200 | B13: Payroll Liabilities | C13: -60000 | D13: 0 | E13: 60000 | F13: Synthetic opening balance | G13: =D13-E13-C13 -> 0
A14: 2300 | B14: VAT / Tax Payable | C14: -100000 | D14: 0 | E14: 100000 | F14: Synthetic opening balance | G14: =D14-E14-C14 -> 0
A15: 3000 | B15: Share Capital | C15: -500000 | D15: 0 | E15: 500000 | F15: Synthetic opening balance | G15: =D15-E15-C15 -> 0
... A30: 7000 | B30: Interest Expense | C30: 0 | D30: 0 | E30: 0 | F30: Synthetic opening balance | G30: =D30-E30-C30 -> 0
A32: TOTAL | C32: =SUM(C4:C30) -> 0 | D32: =SUM(D4:D30) -> 3190000 | E32: =SUM(E4:E30) -> 3190000 | G32: =D32-E32 -> 0

Sheet GL Extract
A1: ERP General Ledger Extract — Jan to Sep 2026
A3: Journal ID | B3: Date | C3: Account Code | D3: Account Name | E3: Management Line | F3: Statement | G3: Debit (£) | H3: Credit (£) | I3: Net Amount (£) | J3: Reference | K3: Description | L3: Source | M3: Month | N3: Control
A4: JE00001 | B4: 46044 | C4: 1100 | D4: =IFERROR(VLOOKUP(C4,'Chart of Accounts'!$A$4:$F$30,2,FALSE),"") -> Trade Receivables | E4: =IFERROR(VLOOKUP(C4,'Chart of Accounts'!$A$4:$F$30,4,FALSE),"") -> Trade Receivables | F4: =IFERROR(VLOOKUP(C4,'Chart of Accounts'!$A$4:$F$30,5,FALSE),"") -> BS | G4: 47208.301 | H4: 0 | I4: =G4-H4 -> 47208.301 | J4: SI-01-001 | K4: Sales invoice — Customer 29 | L4: Sales Ledger | M4: =TEXT(B4,"yyyy-mm") -> 2026-01 | N4: ="OK" -> OK
A5: JE00001 | B5: 46044 | C5: 4000 | D5: =IFERROR(VLOOKUP(C5,'Chart of Accounts'!$A$4:$F$30,2,FALSE),"") -> Product Sales | E5: =IFERROR(VLOOKUP(C5,'Chart of Accounts'!$A$4:$F$30,4,FALSE),"") -> Revenue | F5: =IFERROR(VLOOKUP(C5,'Chart of Accounts'!$A$4:$F$30,5,FALSE),"") -> PL | G5: 0 | H5: 47208.301 | I5: =G5-H5 -> -47208.301 | J5: SI-01-001 | K5: Sales invoice — Customer 29 | L5: Sales Ledger | M5: =TEXT(B5,"yyyy-mm") -> 2026-01 | N5: ="OK" -> OK
A6: JE00001 | B6: 46044 | C6: 5000 | D6: =IFERROR(VLOOKUP(C6,'Chart of Accounts'!$A$4:$F$30,2,FALSE),"") -> Cost of Goods Sold | E6: =IFERROR(VLOOKUP(C6,'Chart of Accounts'!$A$4:$F$30,4,FALSE),"") -> COGS | F6: =IFERROR(VLOOKUP(C6,'Chart of Accounts'!$A$4:$F$30,5,FALSE),"") -> PL | G6: 26200.607 | H6: 0 | I6: =G6-H6 -> 26200.607 | J6: SI-01-001 | K6: Sales invoice — Customer 29 | L6: Sales Ledger | M6: =TEXT(B6,"yyyy-mm") -> 2026-01 | N6: ="OK" -> OK
A7: JE00001 | B7: 46044 | C7: 1200 | D7: =IFERROR(VLOOKUP(C7,'Chart of Accounts'!$A$4:$F$30,2,FALSE),"") -> Inventory | E7: =IFERROR(VLOOKUP(C7,'Chart of Accounts'!$A$4:$F$30,4,FALSE),"") -> Inventory | F7: =IFERROR(VLOOKUP(C7,'Chart of Accounts'!$A$4:$F$30,5,FALSE),"") -> BS | G7: 0 | H7: 26200.607 | I7: =G7-H7 -> -26200.607 | J7: SI-01-001 | K7: Sales invoice — Customer 29 | L7: Sales Ledger | M7: =TEXT(B7,"yyyy-mm") -> 2026-01 | N7: ="OK" -> OK
A8: JE00002 | B8: 46028 | C8: 1100 | D8: =IFERROR(VLOOKUP(C8,'Chart of Accounts'!$A$4:$F$30,2,FALSE),"") -> Trade Receivables | E8: =IFERROR(VLOOKUP(C8,'Chart of Accounts'!$A$4:$F$30,4,FALSE),"") -> Trade Receivables | F8: =IFERROR(VLOOKUP(C8,'Chart of Accounts'!$A$4:$F$30,5,FALSE),"") -> BS | G8: 91301.083 | H8: 0 | I8: =G8-H8 -> 91301.083 | J8: SI-01-002 | K8: Sales invoice — Customer 27 | L8: Sales Ledger | M8: =TEXT(B8,"yyyy-mm") -> 2026-01 | N8: ="OK" -> OK
A9: JE00002 | B9: 46028 | C9: 4000 | D9: =IFERROR(VLOOKUP(C9,'Chart of Accounts'!$A$4:$F$30,2,FALSE),"") -> Product Sales | E9: =IFERROR(VLOOKUP(C9,'Chart of Accounts'!$A$4:$F$30,4,FALSE),"") -> Revenue | F9: =IFERROR(VLOOKUP(C9,'Chart of Accounts'!$A$4:$F$30,5,FALSE),"") -> PL | G9: 0 | H9: 91301.083 | I9: =G9-H9 -> -91301.083 | J9: SI-01-002 | K9: Sales invoice — Customer 27 | L9: Sales Ledger | M9: =TEXT(B9,"yyyy-mm") -> 2026-01 | N9: ="OK" -> OK
A10: JE00002 | B10: 46028 | C10: 5000 | D10: =IFERROR(VLOOKUP(C10,'Chart of Accounts'!$A$4:$F$30,2,FALSE),"") -> Cost of Goods Sold | E10: =IFERROR(VLOOKUP(C10,'Chart of Accounts'!$A$4:$F$30,4,FALSE),"") -> COGS | F10: =IFERROR(VLOOKUP(C10,'Chart of Accounts'!$A$4:$F$30,5,FALSE),"") -> PL | G10: 50672.101 | H10: 0 | I10: =G10-H10 -> 50672.101 | J10: SI-01-002 | K10: Sales invoice — Customer 27 | L10: Sales Ledger | M10: =TEXT(B10,"yyyy-mm") -> 2026-01 | N10: ="OK" -> OK
A11: JE00002 | B11: 46028 | C11: 1200 | D11: =IFERROR(VLOOKUP(C11,'Chart of Accounts'!$A$4:$F$30,2,FALSE),"") -> Inventory | E11: =IFERROR(VLOOKUP(C11,'Chart of Accounts'!$A$4:$F$30,4,FALSE),"") -> Inventory | F11: =IFERROR(VLOOKUP(C11,'Chart of Accounts'!$A$4:$F$30,5,FALSE),"") -> BS | G11: 0 | H11: 50672.101 | I11: =G11-H11 -> -50672.101 | J11: SI-01-002 | K11: Sales invoice — Customer 27 | L11: Sales Ledger | M11: =TEXT(B11,"yyyy-mm") -> 2026-01 | N11: ="OK" -> OK
A12: JE00003 | B12: 46043 | C12: 1100 | D12: =IFERROR(VLOOKUP(C12,'Chart of Accounts'!$A$4:$F$30,2,FALSE),"") -> Trade Receivables | E12: =IFERROR(VLOOKUP(C12,'Chart of Accounts'!$A$4:$F$30,4,FALSE),"") -> Trade Receivables | F12: =IFERROR(VLOOKUP(C12,'Chart of Accounts'!$A$4:$F$30,5,FALSE),"") -> BS | G12: 62537.911 | H12: 0 | I12: =G12-H12 -> 62537.911 | J12: SI-01-003 | K12: Sales invoice — Customer 17 | L12: Sales Ledger | M12: =TEXT(B12,"yyyy-mm") -> 2026-01 | N12: ="OK" -> OK
A13: JE00003 | B13: 46043 | C13: 4000 | D13: =IFERROR(VLOOKUP(C13,'Chart of Accounts'!$A$4:$F$30,2,FALSE),"") -> Product Sales | E13: =IFERROR(VLOOKUP(C13,'Chart of Accounts'!$A$4:$F$30,4,FALSE),"") -> Revenue | F13: =IFERROR(VLOOKUP(C13,'Chart of Accounts'!$A$4:$F$30,5,FALSE),"") -> PL | G13: 0 | H13: 62537.911 | I13: =G13-H13 -> -62537.911 | J13: SI-01-003 | K13: Sales invoice — Customer 17 | L13: Sales Ledger | M13: =TEXT(B13,"yyyy-mm") -> 2026-01 | N13: ="OK" -> OK
A14: JE00003 | B14: 46043 | C14: 5000 | D14: =IFERROR(VLOOKUP(C14,'Chart of Accounts'!$A$4:$F$30,2,FALSE),"") -> Cost of Goods Sold | E14: =IFERROR(VLOOKUP(C14,'Chart of Accounts'!$A$4:$F$30,4,FALSE),"") -> COGS | F14: =IFERROR(VLOOKUP(C14,'Chart of Accounts'!$A$4:$F$30,5,FALSE),"") -> PL | G14: 34708.541 | H14: 0 | I14: =G14-H14 -> 34708.541 | J14: SI-01-003 | K14: Sales invoice — Customer 17 | L14: Sales Ledger | M14: =TEXT(B14,"yyyy-mm") -> 2026-01 | N14: ="OK" -> OK
A15: JE00003 | B15: 46043 | C15: 1200 | D15: =IFERROR(VLOOKUP(C15,'Chart of Accounts'!$A$4:$F$30,2,FALSE),"") -> Inventory | E15: =IFERROR(VLOOKUP(C15,'Chart of Accounts'!$A$4:$F$30,4,FALSE),"") -> Inventory | F15: =IFERROR(VLOOKUP(C15,'Chart of Accounts'!$A$4:$F$30,5,FALSE),"") -> BS | G15: 0 | H15: 34708.541 | I15: =G15-H15 -> -34708.541 | J15: SI-01-003 | K15: Sales invoice — Customer 17 | L15: Sales Ledger | M15: =TEXT(B15,"yyyy-mm") -> 2026-01 | N15: ="OK" -> OK
... A943: JE00353 | B943: 46193 | C943: 1000 | D943: =IFERROR(VLOOKUP(C943,'Chart of Accounts'!$A$4:$F$30,2,FALSE),"") -> Bank | E943: =IFERROR(VLOOKUP(C943,'Chart of Accounts'!$A$4:$F$30,4,FALSE),"") -> Cash | F943: =IFERROR(VLOOKUP(C943,'Chart of Accounts'!$A$4:$F$30,5,FALSE),"") -> BS | G943: 0 | H943: 65000 | I943: =G943-H943 -> -65000 | J943: TAX-0626 | K943: Corporate tax payment on account | L943: Bank | M943: =TEXT(B943,"yyyy-mm") -> 2026-06 | N943: ="OK" -> OK

Sheet Adjustment Journals
A1: September 2026 Month-End Adjustment Journals
A3: Journal ID | B3: Date | C3: Account Code | D3: Account Name | E3: Management Line | F3: Debit (£) | G3: Credit (£) | H3: Net Amount (£) | I3: Description | J3: Support | K3: Source | L3: Approval
A4: AJ001 | B4: 46295 | C4: 6400 | D4: =IFERROR(VLOOKUP(C4,'Chart of Accounts'!$A$4:$F$30,2,FALSE),"") -> Utilities | E4: =IFERROR(VLOOKUP(C4,'Chart of Accounts'!$A$4:$F$30,4,FALSE),"") -> Utilities | F4: 22000 | G4: 0 | H4: =F4-G4 -> 22000 | I4: Sep utilities accrual | J4: Month-end estimate | K4: Synthetic close assumption | L4: Prepared
A5: AJ001 | B5: 46295 | C5: 2100 | D5: =IFERROR(VLOOKUP(C5,'Chart of Accounts'!$A$4:$F$30,2,FALSE),"") -> Accrued Expenses | E5: =IFERROR(VLOOKUP(C5,'Chart of Accounts'!$A$4:$F$30,4,FALSE),"") -> Accrued Expenses | F5: 0 | G5: 22000 | H5: =F5-G5 -> -22000 | I5: Sep utilities accrual | J5: Month-end estimate | K5: Synthetic close assumption | L5: Prepared
A6: AJ002 | B6: 46295 | C6: 6500 | D6: =IFERROR(VLOOKUP(C6,'Chart of Accounts'!$A$4:$F$30,2,FALSE),"") -> Professional Fees | E6: =IFERROR(VLOOKUP(C6,'Chart of Accounts'!$A$4:$F$30,4,FALSE),"") -> Professional Fees | F6: 18000 | G6: 0 | H6: =F6-G6 -> 18000 | I6: Sep professional fees accrual | J6: Month-end estimate | K6: Synthetic close assumption | L6: Prepared
A7: AJ002 | B7: 46295 | C7: 2100 | D7: =IFERROR(VLOOKUP(C7,'Chart of Accounts'!$A$4:$F$30,2,FALSE),"") -> Accrued Expenses | E7: =IFERROR(VLOOKUP(C7,'Chart of Accounts'!$A$4:$F$30,4,FALSE),"") -> Accrued Expenses | F7: 0 | G7: 18000 | H7: =F7-G7 -> -18000 | I7: Sep professional fees accrual | J7: Month-end estimate | K7: Synthetic close assumption | L7: Prepared
A8: AJ003 | B8: 46295 | C8: 6000 | D8: =IFERROR(VLOOKUP(C8,'Chart of Accounts'!$A$4:$F$30,2,FALSE),"") -> Salaries & Wages | E8: =IFERROR(VLOOKUP(C8,'Chart of Accounts'!$A$4:$F$30,4,FALSE),"") -> Salaries | F8: 35000 | G8: 0 | H8: =F8-G8 -> 35000 | I8: Q3 bonus accrual | J8: HR estimate | K8: Synthetic close assumption | L8: Prepared
A9: AJ003 | B9: 46295 | C9: 2100 | D9: =IFERROR(VLOOKUP(C9,'Chart of Accounts'!$A$4:$F$30,2,FALSE),"") -> Accrued Expenses | E9: =IFERROR(VLOOKUP(C9,'Chart of Accounts'!$A$4:$F$30,4,FALSE),"") -> Accrued Expenses | F9: 0 | G9: 35000 | H9: =F9-G9 -> -35000 | I9: Q3 bonus accrual | J9: HR estimate | K9: Synthetic close assumption | L9: Prepared
A10: AJ004 | B10: 46295 | C10: 6800 | D10: =IFERROR(VLOOKUP(C10,'Chart of Accounts'!$A$4:$F$30,2,FALSE),"") -> Depreciation | E10: =IFERROR(VLOOKUP(C10,'Chart of Accounts'!$A$4:$F$30,4,FALSE),"") -> Depreciation | F10: 15000 | G10: 0 | H10: =F10-G10 -> 15000 | I10: Sep depreciation | J10: Fixed asset schedule | K10: Synthetic close assumption | L10: Prepared
A11: AJ004 | B11: 46295 | C11: 1450 | D11: =IFERROR(VLOOKUP(C11,'Chart of Accounts'!$A$4:$F$30,2,FALSE),"") -> Accumulated Depreciation | E11: =IFERROR(VLOOKUP(C11,'Chart of Accounts'!$A$4:$F$30,4,FALSE),"") -> Accumulated Depreciation | F11: 0 | G11: 15000 | H11: =F11-G11 -> -15000 | I11: Sep depreciation | J11: Fixed asset schedule | K11: Synthetic close assumption | L11: Prepared
A12: AJ005 | B12: 46295 | C12: 1300 | D12: =IFERROR(VLOOKUP(C12,'Chart of Accounts'!$A$4:$F$30,2,FALSE),"") -> Prepayments | E12: =IFERROR(VLOOKUP(C12,'Chart of Accounts'!$A$4:$F$30,4,FALSE),"") -> Prepayments | F12: 24000 | G12: 0 | H12: =F12-G12 -> 24000 | I12: Insurance prepayment Oct-Dec | J12: Prepayment schedule | K12: Synthetic close assumption | L12: Prepared
A13: AJ005 | B13: 46295 | C13: 6550 | D13: =IFERROR(VLOOKUP(C13,'Chart of Accounts'!$A$4:$F$30,2,FALSE),"") -> Insurance | E13: =IFERROR(VLOOKUP(C13,'Chart of Accounts'!$A$4:$F$30,4,FALSE),"") -> Insurance | F13: 0 | G13: 24000 | H13: =F13-G13 -> -24000 | I13: Insurance prepayment Oct-Dec | J13: Prepayment schedule | K13: Synthetic close assumption | L13: Prepared
A14: AJ006 | B14: 46295 | C14: 6900 | D14: =IFERROR(VLOOKUP(C14,'Chart of Accounts'!$A$4:$F$30,2,FALSE),"") -> Bad Debt Expense | E14: =IFERROR(VLOOKUP(C14,'Chart of Accounts'!$A$4:$F$30,4,FALSE),"") -> Bad Debt | F14: 5000 | G14: 0 | H14: =F14-G14 -> 5000 | I14: Increase doubtful debt allowance | J14: AR ageing review | K14: Synthetic close assumption | L14: Prepared
A15: AJ006 | B15: 46295 | C15: 1150 | D15: =IFERROR(VLOOKUP(C15,'Chart of Accounts'!$A$4:$F$30,2,FALSE),"") -> Allowance for Doubtful Debts | E15: =IFERROR(VLOOKUP(C15,'Chart of Accounts'!$A$4:$F$30,4,FALSE),"") -> Allowance for Doubtful Debts | F15: 0 | G15: 5000 | H15: =F15-G15 -> -5000 | I15: Increase doubtful debt allowance | J15: AR ageing review | K15: Synthetic close assumption | L15: Prepared
... A17: AJ007 | B17: 46295 | C17: 2100 | D17: =IFERROR(VLOOKUP(C17,'Chart of Accounts'!$A$4:$F$30,2,FALSE),"") -> Accrued Expenses | E17: =IFERROR(VLOOKUP(C17,'Chart of Accounts'!$A$4:$F$30,4,FALSE),"") -> Accrued Expenses | F17: 0 | G17: 30000 | H17: =F17-G17 -> -30000 | I17: Unbilled marketing campaign | J17: Marketing PO review | K17: Synthetic close assumption | L17: Prepared

Sheet Adjusted TB
A1: Adjusted Trial Balance — 30 Sep 2026
A3: Account Code | B3: Account Name | C3: Type | D3: Management Line | E3: Opening (£) | F3: Base GL (£) | G3: Adjustments (£) | H3: Closing (£) | I3: Debit (£) | J3: Credit (£)
A4: 1000 | B4: Bank | C4: Asset | D4: Cash | E4: =SUMIF('Opening TB'!$A$4:$A$30,A4,'Opening TB'!$C$4:$C$30) -> 450000 | F4: =SUMIF('GL Extract'!$C$4:$C$943,A4,'GL Extract'!$I$4:$I$943) -> 407522.22 | G4: =SUMIF('Adjustment Journals'!$C$4:$C$17,A4,'Adjustment Journals'!$H$4:$H$17) -> 0 | H4: =E4+F4+G4 -> 857522.22 | I4: =MAX(H4,0) -> 857522.22 | J4: =MAX(-H4,0) -> 0
A5: 1100 | B5: Trade Receivables | C5: Asset | D5: Trade Receivables | E5: =SUMIF('Opening TB'!$A$4:$A$30,A5,'Opening TB'!$C$4:$C$30) -> 800000 | F5: =SUMIF('GL Extract'!$C$4:$C$943,A5,'GL Extract'!$I$4:$I$943) -> 351225 | G5: =SUMIF('Adjustment Journals'!$C$4:$C$17,A5,'Adjustment Journals'!$H$4:$H$17) -> 0 | H5: =E5+F5+G5 -> 1151225 | I5: =MAX(H5,0) -> 1151225 | J5: =MAX(-H5,0) -> 0
A6: 1150 | B6: Allowance for Doubtful Debts | C6: Asset | D6: Allowance for Doubtful Debts | E6: =SUMIF('Opening TB'!$A$4:$A$30,A6,'Opening TB'!$C$4:$C$30) -> -30000 | F6: =SUMIF('GL Extract'!$C$4:$C$943,A6,'GL Extract'!$I$4:$I$943) -> 0 | G6: =SUMIF('Adjustment Journals'!$C$4:$C$17,A6,'Adjustment Journals'!$H$4:$H$17) -> -5000 | H6: =E6+F6+G6 -> -35000 | I6: =MAX(H6,0) -> 0 | J6: =MAX(-H6,0) -> 35000
A7: 1200 | B7: Inventory | C7: Asset | D7: Inventory | E7: =SUMIF('Opening TB'!$A$4:$A$30,A7,'Opening TB'!$C$4:$C$30) -> 650000 | F7: =SUMIF('GL Extract'!$C$4:$C$943,A7,'GL Extract'!$I$4:$I$943) -> 10084.8 | G7: =SUMIF('Adjustment Journals'!$C$4:$C$17,A7,'Adjustment Journals'!$H$4:$H$17) -> 0 | H7: =E7+F7+G7 -> 660084.8 | I7: =MAX(H7,0) -> 660084.8 | J7: =MAX(-H7,0) -> 0
A8: 1300 | B8: Prepayments | C8: Asset | D8: Prepayments | E8: =SUMIF('Opening TB'!$A$4:$A$30,A8,'Opening TB'!$C$4:$C$30) -> 90000 | F8: =SUMIF('GL Extract'!$C$4:$C$943,A8,'GL Extract'!$I$4:$I$943) -> 0 | G8: =SUMIF('Adjustment Journals'!$C$4:$C$17,A8,'Adjustment Journals'!$H$4:$H$17) -> 24000 | H8: =E8+F8+G8 -> 114000 | I8: =MAX(H8,0) -> 114000 | J8: =MAX(-H8,0) -> 0
A9: 1400 | B9: Property, Plant & Equipment | C9: Asset | D9: Property, Plant & Equipment | E9: =SUMIF('Opening TB'!$A$4:$A$30,A9,'Opening TB'!$C$4:$C$30) -> 1200000 | F9: =SUMIF('GL Extract'!$C$4:$C$943,A9,'GL Extract'!$I$4:$I$943) -> 230000 | G9: =SUMIF('Adjustment Journals'!$C$4:$C$17,A9,'Adjustment Journals'!$H$4:$H$17) -> 0 | H9: =E9+F9+G9 -> 1430000 | I9: =MAX(H9,0) -> 1430000 | J9: =MAX(-H9,0) -> 0
A10: 1450 | B10: Accumulated Depreciation | C10: Asset | D10: Accumulated Depreciation | E10: =SUMIF('Opening TB'!$A$4:$A$30,A10,'Opening TB'!$C$4:$C$30) -> -350000 | F10: =SUMIF('GL Extract'!$C$4:$C$943,A10,'GL Extract'!$I$4:$I$943) -> -120000 | G10: =SUMIF('Adjustment Journals'!$C$4:$C$17,A10,'Adjustment Journals'!$H$4:$H$17) -> -15000 | H10: =E10+F10+G10 -> -485000 | I10: =MAX(H10,0) -> 0 | J10: =MAX(-H10,0) -> 485000
A11: 2000 | B11: Trade Payables | C11: Liability | D11: Trade Payables | E11: =SUMIF('Opening TB'!$A$4:$A$30,A11,'Opening TB'!$C$4:$C$30) -> -600000 | F11: =SUMIF('GL Extract'!$C$4:$C$943,A11,'GL Extract'!$I$4:$I$943) -> -1039932 | G11: =SUMIF('Adjustment Journals'!$C$4:$C$17,A11,'Adjustment Journals'!$H$4:$H$17) -> 0 | H11: =E11+F11+G11 -> -1639932 | I11: =MAX(H11,0) -> 0 | J11: =MAX(-H11,0) -> 1639932
A12: 2100 | B12: Accrued Expenses | C12: Liability | D12: Accrued Expenses | E12: =SUMIF('Opening TB'!$A$4:$A$30,A12,'Opening TB'!$C$4:$C$30) -> -150000 | F12: =SUMIF('GL Extract'!$C$4:$C$943,A12,'GL Extract'!$I$4:$I$943) -> 0 | G12: =SUMIF('Adjustment Journals'!$C$4:$C$17,A12,'Adjustment Journals'!$H$4:$H$17) -> -105000 | H12: =E12+F12+G12 -> -255000 | I12: =MAX(H12,0) -> 0 | J12: =MAX(-H12,0) -> 255000
A13: 2200 | B13: Payroll Liabilities | C13: Liability | D13: Payroll Liabilities | E13: =SUMIF('Opening TB'!$A$4:$A$30,A13,'Opening TB'!$C$4:$C$30) -> -60000 | F13: =SUMIF('GL Extract'!$C$4:$C$943,A13,'GL Extract'!$I$4:$I$943) -> 0 | G13: =SUMIF('Adjustment Journals'!$C$4:$C$17,A13,'Adjustment Journals'!$H$4:$H$17) -> 0 | H13: =E13+F13+G13 -> -60000 | I13: =MAX(H13,0) -> 0 | J13: =MAX(-H13,0) -> 60000
A14: 2300 | B14: VAT / Tax Payable | C14: Liability | D14: Tax Payable | E14: =SUMIF('Opening TB'!$A$4:$A$30,A14,'Opening TB'!$C$4:$C$30) -> -100000 | F14: =SUMIF('GL Extract'!$C$4:$C$943,A14,'GL Extract'!$I$4:$I$943) -> 65000 | G14: =SUMIF('Adjustment Journals'!$C$4:$C$17,A14,'Adjustment Journals'!$H$4:$H$17) -> 0 | H14: =E14+F14+G14 -> -35000 | I14: =MAX(H14,0) -> 0 | J14: =MAX(-H14,0) -> 35000
A15: 3000 | B15: Share Capital | C15: Equity | D15: Share Capital | E15: =SUMIF('Opening TB'!$A$4:$A$30,A15,'Opening TB'!$C$4:$C$30) -> -500000 | F15: =SUMIF('GL Extract'!$C$4:$C$943,A15,'GL Extract'!$I$4:$I$943) -> 0 | G15: =SUMIF('Adjustment Journals'!$C$4:$C$17,A15,'Adjustment Journals'!$H$4:$H$17) -> 0 | H15: =E15+F15+G15 -> -500000 | I15: =MAX(H15,0) -> 0 | J15: =MAX(-H15,0) -> 500000
... A30: 7000 | B30: Interest Expense | C30: Expense | D30: Interest | E30: =SUMIF('Opening TB'!$A$4:$A$30,A30,'Opening TB'!$C$4:$C$30) -> 0 | F30: =SUMIF('GL Extract'!$C$4:$C$943,A30,'GL Extract'!$I$4:$I$943) -> 49500 | G30: =SUMIF('Adjustment Journals'!$C$4:$C$17,A30,'Adjustment Journals'!$H$4:$H$17) -> 0 | H30: =E30+F30+G30 -> 49500 | I30: =MAX(H30,0) -> 49500 | J30: =MAX(-H30,0) -> 0
A32: TOTAL | E32: =SUM(E4:E30) -> 0 | F32: =SUM(F4:F30) -> -2.6193447e-09 | G32: =SUM(G4:G30) -> 0 | H32: =SUM(H4:H30) -> -2.6193447e-09 | I32: =SUM(I4:I30) -> 12709932 | J32: =SUM(J4:J30) -> 12709932

Sheet Budget
A1: FY2026 Management Budget — Jan to Sep
A3: Management Line | B3: Jan-26 | C3: Feb-26 | D3: Mar-26 | E3: Apr-26 | F3: May-26 | G3: Jun-26 | H3: Jul-26 | I3: Aug-26 | J3: Sep-26 | K3: YTD
A4: Revenue | B4: 805000 | C4: 835000 | D4: 865000 | E4: 895000 | F4: 925000 | G4: 950000 | H4: 965000 | I4: 985000 | J4: 1005000 | K4: 8230000
A5: COGS | B5: 442750 | C5: 459250 | D5: 475750 | E5: 492250 | F5: 508750 | G5: 522500 | H5: 530750 | I5: 541750 | J5: 552750 | K5: 4526500
A6: Salaries | B6: 180000 | C6: 181000 | D6: 182000 | E6: 183000 | F6: 184000 | G6: 186000 | H6: 188000 | I6: 190000 | J6: 192000 | K6: 1666000
A7: Employer Costs | B7: 24300 | C7: 24435 | D7: 24570 | E7: 24705 | F7: 24840 | G7: 25110 | H7: 25380 | I7: 25650 | J7: 25920 | K7: 224910
A8: Marketing | B8: 60000 | C8: 62200 | D8: 64400 | E8: 66600 | F8: 68800 | G8: 71000 | H8: 73200 | I8: 75400 | J8: 77600 | K8: 619200
A9: Rent | B9: 52000 | C9: 52000 | D9: 52000 | E9: 52000 | F9: 52000 | G9: 52000 | H9: 52000 | I9: 52000 | J9: 52000 | K9: 468000
A10: Utilities | B10: 20000 | C10: 20300 | D10: 20600 | E10: 20900 | F10: 21200 | G10: 21500 | H10: 21800 | I10: 22100 | J10: 22400 | K10: 190800
A11: Professional Fees | B11: 14500 | C11: 14950 | D11: 15400 | E11: 15850 | F11: 16300 | G11: 16750 | H11: 17200 | I11: 17650 | J11: 18100 | K11: 146700
A12: Insurance | B12: 8000 | C12: 8000 | D12: 8000 | E12: 8000 | F12: 8000 | G12: 8000 | H12: 8000 | I12: 8000 | J12: 8000 | K12: 72000
A13: Software & IT | B13: 23000 | C13: 23000 | D13: 23000 | E13: 23000 | F13: 23000 | G13: 23000 | H13: 23000 | I13: 23000 | J13: 23000 | K13: 207000
A14: Travel | B14: 8000 | C14: 8250 | D14: 8500 | E14: 8750 | F14: 9000 | G14: 9250 | H14: 9500 | I14: 9750 | J14: 10000 | K14: 81000
A15: Depreciation | B15: 15000 | C15: 15000 | D15: 15000 | E15: 15000 | F15: 15000 | G15: 15000 | H15: 15000 | I15: 15000 | J15: 15000 | K15: 135000
... A17: Interest | B17: 5500 | C17: 5500 | D17: 5500 | E17: 5500 | F17: 5500 | G17: 5500 | H17: 5500 | I17: 5500 | J17: 5500 | K17: 49500

Sheet Management P&L
A1: Management Profit & Loss — Jan to Sep 2026
A3: Management Line | B3: Jan-26 | C3: Feb-26 | D3: Mar-26 | E3: Apr-26 | F3: May-26 | G3: Jun-26 | H3: Jul-26 | I3: Aug-26 | J3: Sep-26 | K3: YTD Actual | L3: YTD Budget | M3: Var £ | N3: Var %
A4: Revenue | B4: =-1*(SUMIFS('GL Extract'!$I$4:$I$943,'GL Extract'!$C$4:$C$943,"4000",'GL Extract'!$B$4:$B$943,">="&DATE(2026,1,1),'GL Extract'!$B$4:$B$943,"<"&DATE(2026,2,1))) -> 820000 | C4: =-1*(SUMIFS('GL Extract'!$I$4:$I$943,'GL Extract'!$C$4:$C$943,"4000",'GL Extract'!$B$4:$B$943,">="&DATE(2026,2,1),'GL Extract'!$B$4:$B$943,"<"&DATE(2026,3,1))) -> 845000 | D4: =-1*(SUMIFS('GL Extract'!$I$4:$I$943,'GL Extract'!$C$4:$C$943,"4000",'GL Extract'!$B$4:$B$943,">="&DATE(2026,3,1),'GL Extract'!$B$4:$B$943,"<"&DATE(2026,4,1))) -> 875000 | E4: =-1*(SUMIFS('GL Extract'!$I$4:$I$943,'GL Extract'!$C$4:$C$943,"4000",'GL Extract'!$B$4:$B$943,">="&DATE(2026,4,1),'GL Extract'!$B$4:$B$943,"<"&DATE(2026,5,1))) -> 900000 | F4: =-1*(SUMIFS('GL Extract'!$I$4:$I$943,'GL Extract'!$C$4:$C$943,"4000",'GL Extract'!$B$4:$B$943,">="&DATE(2026,5,1),'GL Extract'!$B$4:$B$943,"<"&DATE(2026,6,1))) -> 930000 | G4: =-1*(SUMIFS('GL Extract'!$I$4:$I$943,'GL Extract'!$C$4:$C$943,"4000",'GL Extract'!$B$4:$B$943,">="&DATE(2026,6,1),'GL Extract'!$B$4:$B$943,"<"&DATE(2026,7,1))) -> 955000 | H4: =-1*(SUMIFS('GL Extract'!$I$4:$I$943,'GL Extract'!$C$4:$C$943,"4000",'GL Extract'!$B$4:$B$943,">="&DATE(2026,7,1),'GL Extract'!$B$4:$B$943,"<"&DATE(2026,8,1))) -> 970000 | I4: =-1*(SUMIFS('GL Extract'!$I$4:$I$943,'GL Extract'!$C$4:$C$943,"4000",'GL Extract'!$B$4:$B$943,">="&DATE(2026,8,1),'GL Extract'!$B$4:$B$943,"<"&DATE(2026,9,1))) -> 990000 | J4: =-1*(SUMIFS('GL Extract'!$I$4:$I$943,'GL Extract'!$C$4:$C$943,"4000",'GL Extract'!$B$4:$B$943,">="&DATE(2026,9,1),'GL Extract'!$B$4:$B$943,"<"&DATE(2026,10,1))+SUMIF('Adjustment Journals'!$C$4:$C$17,"4000",'Adjustment Journals'!$H$4:$H$17)) -> 1015000 | K4: =SUM(B4:J4) -> 8300000 | L4: =Budget!K4 -> 8230000 | M4: =K4-L4 -> 70000 | N4: =IFERROR(M4/L4,0) -> 0.0085054678
A5: COGS | B5: =1*(SUMIFS('GL Extract'!$I$4:$I$943,'GL Extract'!$C$4:$C$943,"5000",'GL Extract'!$B$4:$B$943,">="&DATE(2026,1,1),'GL Extract'!$B$4:$B$943,"<"&DATE(2026,2,1))) -> 455100 | C5: =1*(SUMIFS('GL Extract'!$I$4:$I$943,'GL Extract'!$C$4:$C$943,"5000",'GL Extract'!$B$4:$B$943,">="&DATE(2026,2,1),'GL Extract'!$B$4:$B$943,"<"&DATE(2026,3,1))) -> 467285 | D5: =1*(SUMIFS('GL Extract'!$I$4:$I$943,'GL Extract'!$C$4:$C$943,"5000",'GL Extract'!$B$4:$B$943,">="&DATE(2026,3,1),'GL Extract'!$B$4:$B$943,"<"&DATE(2026,4,1))) -> 483000 | E5: =1*(SUMIFS('GL Extract'!$I$4:$I$943,'GL Extract'!$C$4:$C$943,"5000",'GL Extract'!$B$4:$B$943,">="&DATE(2026,4,1),'GL Extract'!$B$4:$B$943,"<"&DATE(2026,5,1))) -> 495000 | F5: =1*(SUMIFS('GL Extract'!$I$4:$I$943,'GL Extract'!$C$4:$C$943,"5000",'GL Extract'!$B$4:$B$943,">="&DATE(2026,5,1),'GL Extract'!$B$4:$B$943,"<"&DATE(2026,6,1))) -> 509640 | G5: =1*(SUMIFS('GL Extract'!$I$4:$I$943,'GL Extract'!$C$4:$C$943,"5000",'GL Extract'!$B$4:$B$943,">="&DATE(2026,6,1),'GL Extract'!$B$4:$B$943,"<"&DATE(2026,7,1))) -> 524295 | H5: =1*(SUMIFS('GL Extract'!$I$4:$I$943,'GL Extract'!$C$4:$C$943,"5000",'GL Extract'!$B$4:$B$943,">="&DATE(2026,7,1),'GL Extract'!$B$4:$B$943,"<"&DATE(2026,8,1))) -> 530590 | I5: =1*(SUMIFS('GL Extract'!$I$4:$I$943,'GL Extract'!$C$4:$C$943,"5000",'GL Extract'!$B$4:$B$943,">="&DATE(2026,8,1),'GL Extract'!$B$4:$B$943,"<"&DATE(2026,9,1))) -> 540540 | J5: =1*(SUMIFS('GL Extract'!$I$4:$I$943,'GL Extract'!$C$4:$C$943,"5000",'GL Extract'!$B$4:$B$943,">="&DATE(2026,9,1),'GL Extract'!$B$4:$B$943,"<"&DATE(2026,10,1))+SUMIF('Adjustment Journals'!$C$4:$C$17,"5000",'Adjustment Journals'!$H$4:$H$17)) -> 553175 | K5: =SUM(B5:J5) -> 4558625 | L5: =Budget!K5 -> 4526500 | M5: =K5-L5 -> 32125 | N5: =IFERROR(M5/L5,0) -> 0.0070970949
A6: Gross Profit | B6: =B4-B5 -> 364900 | C6: =C4-C5 -> 377715 | D6: =D4-D5 -> 392000 | E6: =E4-E5 -> 405000 | F6: =F4-F5 -> 420360 | G6: =G4-G5 -> 430705 | H6: =H4-H5 -> 439410 | I6: =I4-I5 -> 449460 | J6: =J4-J5 -> 461825 | K6: =SUM(B6:J6) -> 3741375 | L6: =L4-L5 -> 3703500 | M6: =K6-L6 -> 37875 | N6: =IFERROR(M6/L6,0) -> 0.010226812
A7: Gross Margin % | B7: =IFERROR(B6/B4,0) -> 0.445 | C7: =IFERROR(C6/C4,0) -> 0.447 | D7: =IFERROR(D6/D4,0) -> 0.448 | E7: =IFERROR(E6/E4,0) -> 0.45 | F7: =IFERROR(F6/F4,0) -> 0.452 | G7: =IFERROR(G6/G4,0) -> 0.451 | H7: =IFERROR(H6/H4,0) -> 0.453 | I7: =IFERROR(I6/I4,0) -> 0.454 | ... L7: =IFERROR(L6/L4,0) -> 0.45 | M7: =K7-L7 -> 0.00076807229 | N7: -
A8: Salaries | B8: =1*(SUMIFS('GL Extract'!$I$4:$I$943,'GL Extract'!$C$4:$C$943,"6000",'GL Extract'!$B$4:$B$943,">="&DATE(2026,1,1),'GL Extract'!$B$4:$B$943,"<"&DATE(2026,2,1))) -> 183571.92 | C8: =1*(SUMIFS('GL Extract'!$I$4:$I$943,'GL Extract'!$C$4:$C$943,"6000",'GL Extract'!$B$4:$B$943,">="&DATE(2026,2,1),'GL Extract'!$B$4:$B$943,"<"&DATE(2026,3,1))) -> 180967.2 | D8: =1*(SUMIFS('GL Extract'!$I$4:$I$943,'GL Extract'!$C$4:$C$943,"6000",'GL Extract'!$B$4:$B$943,">="&DATE(2026,3,1),'GL Extract'!$B$4:$B$943,"<"&DATE(2026,4,1))) -> 184387.08 | E8: =1*(SUMIFS('GL Extract'!$I$4:$I$943,'GL Extract'!$C$4:$C$943,"6000",'GL Extract'!$B$4:$B$943,">="&DATE(2026,4,1),'GL Extract'!$B$4:$B$943,"<"&DATE(2026,5,1))) -> 181710.98 | F8: =1*(SUMIFS('GL Extract'!$I$4:$I$943,'GL Extract'!$C$4:$C$943,"6000",'GL Extract'!$B$4:$B$943,">="&DATE(2026,5,1),'GL Extract'!$B$4:$B$943,"<"&DATE(2026,6,1))) -> 185478.46 | G8: =1*(SUMIFS('GL Extract'!$I$4:$I$943,'GL Extract'!$C$4:$C$943,"6000",'GL Extract'!$B$4:$B$943,">="&DATE(2026,6,1),'GL Extract'!$B$4:$B$943,"<"&DATE(2026,7,1))) -> 187666.59 | H8: =1*(SUMIFS('GL Extract'!$I$4:$I$943,'GL Extract'!$C$4:$C$943,"6000",'GL Extract'!$B$4:$B$943,">="&DATE(2026,7,1),'GL Extract'!$B$4:$B$943,"<"&DATE(2026,8,1))) -> 187046.19 | I8: =1*(SUMIFS('GL Extract'!$I$4:$I$943,'GL Extract'!$C$4:$C$943,"6000",'GL Extract'!$B$4:$B$943,">="&DATE(2026,8,1),'GL Extract'!$B$4:$B$943,"<"&DATE(2026,9,1))) -> 190383.35 | J8: =1*(SUMIFS('GL Extract'!$I$4:$I$943,'GL Extract'!$C$4:$C$943,"6000",'GL Extract'!$B$4:$B$943,">="&DATE(2026,9,1),'GL Extract'!$B$4:$B$943,"<"&DATE(2026,10,1))+SUMIF('Adjustment Journals'!$C$4:$C$17,"6000",'Adjustment Journals'!$H$4:$H$17)) -> 228218.54 | K8: =SUM(B8:J8) -> 1709430.3 | L8: =Budget!K6 -> 1666000 | M8: =K8-L8 -> 43430.304 | N8: =IFERROR(M8/L8,0) -> 0.02606861
A9: Employer Costs | B9: =1*(SUMIFS('GL Extract'!$I$4:$I$943,'GL Extract'!$C$4:$C$943,"6100",'GL Extract'!$B$4:$B$943,">="&DATE(2026,1,1),'GL Extract'!$B$4:$B$943,"<"&DATE(2026,2,1))) -> 24782.21 | C9: =1*(SUMIFS('GL Extract'!$I$4:$I$943,'GL Extract'!$C$4:$C$943,"6100",'GL Extract'!$B$4:$B$943,">="&DATE(2026,2,1),'GL Extract'!$B$4:$B$943,"<"&DATE(2026,3,1))) -> 24430.572 | D9: =1*(SUMIFS('GL Extract'!$I$4:$I$943,'GL Extract'!$C$4:$C$943,"6100",'GL Extract'!$B$4:$B$943,">="&DATE(2026,3,1),'GL Extract'!$B$4:$B$943,"<"&DATE(2026,4,1))) -> 24892.256 | E9: =1*(SUMIFS('GL Extract'!$I$4:$I$943,'GL Extract'!$C$4:$C$943,"6100",'GL Extract'!$B$4:$B$943,">="&DATE(2026,4,1),'GL Extract'!$B$4:$B$943,"<"&DATE(2026,5,1))) -> 24530.982 | F9: =1*(SUMIFS('GL Extract'!$I$4:$I$943,'GL Extract'!$C$4:$C$943,"6100",'GL Extract'!$B$4:$B$943,">="&DATE(2026,5,1),'GL Extract'!$B$4:$B$943,"<"&DATE(2026,6,1))) -> 25039.592 | G9: =1*(SUMIFS('GL Extract'!$I$4:$I$943,'GL Extract'!$C$4:$C$943,"6100",'GL Extract'!$B$4:$B$943,">="&DATE(2026,6,1),'GL Extract'!$B$4:$B$943,"<"&DATE(2026,7,1))) -> 25334.99 | H9: =1*(SUMIFS('GL Extract'!$I$4:$I$943,'GL Extract'!$C$4:$C$943,"6100",'GL Extract'!$B$4:$B$943,">="&DATE(2026,7,1),'GL Extract'!$B$4:$B$943,"<"&DATE(2026,8,1))) -> 25251.236 | I9: =1*(SUMIFS('GL Extract'!$I$4:$I$943,'GL Extract'!$C$4:$C$943,"6100",'GL Extract'!$B$4:$B$943,">="&DATE(2026,8,1),'GL Extract'!$B$4:$B$943,"<"&DATE(2026,9,1))) -> 25701.752 | J9: =1*(SUMIFS('GL Extract'!$I$4:$I$943,'GL Extract'!$C$4:$C$943,"6100",'GL Extract'!$B$4:$B$943,">="&DATE(2026,9,1),'GL Extract'!$B$4:$B$943,"<"&DATE(2026,10,1))+SUMIF('Adjustment Journals'!$C$4:$C$17,"6100",'Adjustment Journals'!$H$4:$H$17)) -> 26084.502 | K9: =SUM(B9:J9) -> 226048.09 | L9: =Budget!K7 -> 224910 | M9: =K9-L9 -> 1138.091 | N9: =IFERROR(M9/L9,0) -> 0.0050602064
A10: Marketing | B10: =1*(SUMIFS('GL Extract'!$I$4:$I$943,'GL Extract'!$C$4:$C$943,"6200",'GL Extract'!$B$4:$B$943,">="&DATE(2026,1,1),'GL Extract'!$B$4:$B$943,"<"&DATE(2026,2,1))) -> 60208.157 | C10: =1*(SUMIFS('GL Extract'!$I$4:$I$943,'GL Extract'!$C$4:$C$943,"6200",'GL Extract'!$B$4:$B$943,">="&DATE(2026,2,1),'GL Extract'!$B$4:$B$943,"<"&DATE(2026,3,1))) -> 65397.667 | D10: =1*(SUMIFS('GL Extract'!$I$4:$I$943,'GL Extract'!$C$4:$C$943,"6200",'GL Extract'!$B$4:$B$943,">="&DATE(2026,3,1),'GL Extract'!$B$4:$B$943,"<"&DATE(2026,4,1))) -> 61713.152 | E10: =1*(SUMIFS('GL Extract'!$I$4:$I$943,'GL Extract'!$C$4:$C$943,"6200",'GL Extract'!$B$4:$B$943,">="&DATE(2026,4,1),'GL Extract'!$B$4:$B$943,"<"&DATE(2026,5,1))) -> 70443.091 | F10: =1*(SUMIFS('GL Extract'!$I$4:$I$943,'GL Extract'!$C$4:$C$943,"6200",'GL Extract'!$B$4:$B$943,">="&DATE(2026,5,1),'GL Extract'!$B$4:$B$943,"<"&DATE(2026,6,1))) -> 67283.626 | G10: =1*(SUMIFS('GL Extract'!$I$4:$I$943,'GL Extract'!$C$4:$C$943,"6200",'GL Extract'!$B$4:$B$943,">="&DATE(2026,6,1),'GL Extract'!$B$4:$B$943,"<"&DATE(2026,7,1))) -> 74360.051 | H10: =1*(SUMIFS('GL Extract'!$I$4:$I$943,'GL Extract'!$C$4:$C$943,"6200",'GL Extract'!$B$4:$B$943,">="&DATE(2026,7,1),'GL Extract'!$B$4:$B$943,"<"&DATE(2026,8,1))) -> 70152.018 | I10: =1*(SUMIFS('GL Extract'!$I$4:$I$943,'GL Extract'!$C$4:$C$943,"6200",'GL Extract'!$B$4:$B$943,">="&DATE(2026,8,1),'GL Extract'!$B$4:$B$943,"<"&DATE(2026,9,1))) -> 76119.34 | J10: =1*(SUMIFS('GL Extract'!$I$4:$I$943,'GL Extract'!$C$4:$C$943,"6200",'GL Extract'!$B$4:$B$943,">="&DATE(2026,9,1),'GL Extract'!$B$4:$B$943,"<"&DATE(2026,10,1))+SUMIF('Adjustment Journals'!$C$4:$C$17,"6200",'Adjustment Journals'!$H$4:$H$17)) -> 102743.53 | K10: =SUM(B10:J10) -> 648420.63 | L10: =Budget!K8 -> 619200 | M10: =K10-L10 -> 29220.634 | N10: =IFERROR(M10/L10,0) -> 0.047190947
A11: Rent | B11: =1*(SUMIFS('GL Extract'!$I$4:$I$943,'GL Extract'!$C$4:$C$943,"6300",'GL Extract'!$B$4:$B$943,">="&DATE(2026,1,1),'GL Extract'!$B$4:$B$943,"<"&DATE(2026,2,1))) -> 52000 | C11: =1*(SUMIFS('GL Extract'!$I$4:$I$943,'GL Extract'!$C$4:$C$943,"6300",'GL Extract'!$B$4:$B$943,">="&DATE(2026,2,1),'GL Extract'!$B$4:$B$943,"<"&DATE(2026,3,1))) -> 52000 | D11: =1*(SUMIFS('GL Extract'!$I$4:$I$943,'GL Extract'!$C$4:$C$943,"6300",'GL Extract'!$B$4:$B$943,">="&DATE(2026,3,1),'GL Extract'!$B$4:$B$943,"<"&DATE(2026,4,1))) -> 52000 | E11: =1*(SUMIFS('GL Extract'!$I$4:$I$943,'GL Extract'!$C$4:$C$943,"6300",'GL Extract'!$B$4:$B$943,">="&DATE(2026,4,1),'GL Extract'!$B$4:$B$943,"<"&DATE(2026,5,1))) -> 52000 | F11: =1*(SUMIFS('GL Extract'!$I$4:$I$943,'GL Extract'!$C$4:$C$943,"6300",'GL Extract'!$B$4:$B$943,">="&DATE(2026,5,1),'GL Extract'!$B$4:$B$943,"<"&DATE(2026,6,1))) -> 52000 | G11: =1*(SUMIFS('GL Extract'!$I$4:$I$943,'GL Extract'!$C$4:$C$943,"6300",'GL Extract'!$B$4:$B$943,">="&DATE(2026,6,1),'GL Extract'!$B$4:$B$943,"<"&DATE(2026,7,1))) -> 52000 | H11: =1*(SUMIFS('GL Extract'!$I$4:$I$943,'GL Extract'!$C$4:$C$943,"6300",'GL Extract'!$B$4:$B$943,">="&DATE(2026,7,1),'GL Extract'!$B$4:$B$943,"<"&DATE(2026,8,1))) -> 52000 | I11: =1*(SUMIFS('GL Extract'!$I$4:$I$943,'GL Extract'!$C$4:$C$943,"6300",'GL Extract'!$B$4:$B$943,">="&DATE(2026,8,1),'GL Extract'!$B$4:$B$943,"<"&DATE(2026,9,1))) -> 52000 | J11: =1*(SUMIFS('GL Extract'!$I$4:$I$943,'GL Extract'!$C$4:$C$943,"6300",'GL Extract'!$B$4:$B$943,">="&DATE(2026,9,1),'GL Extract'!$B$4:$B$943,"<"&DATE(2026,10,1))+SUMIF('Adjustment Journals'!$C$4:$C$17,"6300",'Adjustment Journals'!$H$4:$H$17)) -> 52000 | K11: =SUM(B11:J11) -> 468000 | L11: =Budget!K9 -> 468000 | M11: =K11-L11 -> 0 | N11: =IFERROR(M11/L11,0) -> 0
A12: Utilities | B12: =1*(SUMIFS('GL Extract'!$I$4:$I$943,'GL Extract'!$C$4:$C$943,"6400",'GL Extract'!$B$4:$B$943,">="&DATE(2026,1,1),'GL Extract'!$B$4:$B$943,"<"&DATE(2026,2,1))) -> 19822.433 | C12: =1*(SUMIFS('GL Extract'!$I$4:$I$943,'GL Extract'!$C$4:$C$943,"6400",'GL Extract'!$B$4:$B$943,">="&DATE(2026,2,1),'GL Extract'!$B$4:$B$943,"<"&DATE(2026,3,1))) -> 20248.498 | D12: =1*(SUMIFS('GL Extract'!$I$4:$I$943,'GL Extract'!$C$4:$C$943,"6400",'GL Extract'!$B$4:$B$943,">="&DATE(2026,3,1),'GL Extract'!$B$4:$B$943,"<"&DATE(2026,4,1))) -> 20775.912 | E12: =1*(SUMIFS('GL Extract'!$I$4:$I$943,'GL Extract'!$C$4:$C$943,"6400",'GL Extract'!$B$4:$B$943,">="&DATE(2026,4,1),'GL Extract'!$B$4:$B$943,"<"&DATE(2026,5,1))) -> 19940.763 | F12: =1*(SUMIFS('GL Extract'!$I$4:$I$943,'GL Extract'!$C$4:$C$943,"6400",'GL Extract'!$B$4:$B$943,">="&DATE(2026,5,1),'GL Extract'!$B$4:$B$943,"<"&DATE(2026,6,1))) -> 21051.681 | G12: =1*(SUMIFS('GL Extract'!$I$4:$I$943,'GL Extract'!$C$4:$C$943,"6400",'GL Extract'!$B$4:$B$943,">="&DATE(2026,6,1),'GL Extract'!$B$4:$B$943,"<"&DATE(2026,7,1))) -> 21369.877 | H12: =1*(SUMIFS('GL Extract'!$I$4:$I$943,'GL Extract'!$C$4:$C$943,"6400",'GL Extract'!$B$4:$B$943,">="&DATE(2026,7,1),'GL Extract'!$B$4:$B$943,"<"&DATE(2026,8,1))) -> 20812.954 | I12: =1*(SUMIFS('GL Extract'!$I$4:$I$943,'GL Extract'!$C$4:$C$943,"6400",'GL Extract'!$B$4:$B$943,">="&DATE(2026,8,1),'GL Extract'!$B$4:$B$943,"<"&DATE(2026,9,1))) -> 21739.113 | J12: =1*(SUMIFS('GL Extract'!$I$4:$I$943,'GL Extract'!$C$4:$C$943,"6400",'GL Extract'!$B$4:$B$943,">="&DATE(2026,9,1),'GL Extract'!$B$4:$B$943,"<"&DATE(2026,10,1))+SUMIF('Adjustment Journals'!$C$4:$C$17,"6400",'Adjustment Journals'!$H$4:$H$17)) -> 22000 | K12: =SUM(B12:J12) -> 187761.23 | L12: =Budget!K10 -> 190800 | M12: =K12-L12 -> -3038.7693 | N12: =IFERROR(M12/L12,0) -> -0.015926464
A13: Professional Fees | B13: =1*(SUMIFS('GL Extract'!$I$4:$I$943,'GL Extract'!$C$4:$C$943,"6500",'GL Extract'!$B$4:$B$943,">="&DATE(2026,1,1),'GL Extract'!$B$4:$B$943,"<"&DATE(2026,2,1))) -> 14134.749 | C13: =1*(SUMIFS('GL Extract'!$I$4:$I$943,'GL Extract'!$C$4:$C$943,"6500",'GL Extract'!$B$4:$B$943,">="&DATE(2026,2,1),'GL Extract'!$B$4:$B$943,"<"&DATE(2026,3,1))) -> 14572.913 | D13: =1*(SUMIFS('GL Extract'!$I$4:$I$943,'GL Extract'!$C$4:$C$943,"6500",'GL Extract'!$B$4:$B$943,">="&DATE(2026,3,1),'GL Extract'!$B$4:$B$943,"<"&DATE(2026,4,1))) -> 14928.638 | E13: =1*(SUMIFS('GL Extract'!$I$4:$I$943,'GL Extract'!$C$4:$C$943,"6500",'GL Extract'!$B$4:$B$943,">="&DATE(2026,4,1),'GL Extract'!$B$4:$B$943,"<"&DATE(2026,5,1))) -> 14077.717 | F13: =1*(SUMIFS('GL Extract'!$I$4:$I$943,'GL Extract'!$C$4:$C$943,"6500",'GL Extract'!$B$4:$B$943,">="&DATE(2026,5,1),'GL Extract'!$B$4:$B$943,"<"&DATE(2026,6,1))) -> 14690.145 | G13: =1*(SUMIFS('GL Extract'!$I$4:$I$943,'GL Extract'!$C$4:$C$943,"6500",'GL Extract'!$B$4:$B$943,">="&DATE(2026,6,1),'GL Extract'!$B$4:$B$943,"<"&DATE(2026,7,1))) -> 16639.717 | H13: =1*(SUMIFS('GL Extract'!$I$4:$I$943,'GL Extract'!$C$4:$C$943,"6500",'GL Extract'!$B$4:$B$943,">="&DATE(2026,7,1),'GL Extract'!$B$4:$B$943,"<"&DATE(2026,8,1))) -> 16742.389 | I13: =1*(SUMIFS('GL Extract'!$I$4:$I$943,'GL Extract'!$C$4:$C$943,"6500",'GL Extract'!$B$4:$B$943,">="&DATE(2026,8,1),'GL Extract'!$B$4:$B$943,"<"&DATE(2026,9,1))) -> 16573.924 | J13: =1*(SUMIFS('GL Extract'!$I$4:$I$943,'GL Extract'!$C$4:$C$943,"6500",'GL Extract'!$B$4:$B$943,">="&DATE(2026,9,1),'GL Extract'!$B$4:$B$943,"<"&DATE(2026,10,1))+SUMIF('Adjustment Journals'!$C$4:$C$17,"6500",'Adjustment Journals'!$H$4:$H$17)) -> 18000 | K13: =SUM(B13:J13) -> 140360.19 | L13: =Budget!K11 -> 146700 | M13: =K13-L13 -> -6339.8076 | N13: =IFERROR(M13/L13,0) -> -0.043216139
A14: Insurance | B14: =1*(SUMIFS('GL Extract'!$I$4:$I$943,'GL Extract'!$C$4:$C$943,"6550",'GL Extract'!$B$4:$B$943,">="&DATE(2026,1,1),'GL Extract'!$B$4:$B$943,"<"&DATE(2026,2,1))) -> 96000 | C14: =1*(SUMIFS('GL Extract'!$I$4:$I$943,'GL Extract'!$C$4:$C$943,"6550",'GL Extract'!$B$4:$B$943,">="&DATE(2026,2,1),'GL Extract'!$B$4:$B$943,"<"&DATE(2026,3,1))) -> 0 | D14: =1*(SUMIFS('GL Extract'!$I$4:$I$943,'GL Extract'!$C$4:$C$943,"6550",'GL Extract'!$B$4:$B$943,">="&DATE(2026,3,1),'GL Extract'!$B$4:$B$943,"<"&DATE(2026,4,1))) -> 0 | E14: =1*(SUMIFS('GL Extract'!$I$4:$I$943,'GL Extract'!$C$4:$C$943,"6550",'GL Extract'!$B$4:$B$943,">="&DATE(2026,4,1),'GL Extract'!$B$4:$B$943,"<"&DATE(2026,5,1))) -> 0 | F14: =1*(SUMIFS('GL Extract'!$I$4:$I$943,'GL Extract'!$C$4:$C$943,"6550",'GL Extract'!$B$4:$B$943,">="&DATE(2026,5,1),'GL Extract'!$B$4:$B$943,"<"&DATE(2026,6,1))) -> 0 | G14: =1*(SUMIFS('GL Extract'!$I$4:$I$943,'GL Extract'!$C$4:$C$943,"6550",'GL Extract'!$B$4:$B$943,">="&DATE(2026,6,1),'GL Extract'!$B$4:$B$943,"<"&DATE(2026,7,1))) -> 0 | H14: =1*(SUMIFS('GL Extract'!$I$4:$I$943,'GL Extract'!$C$4:$C$943,"6550",'GL Extract'!$B$4:$B$943,">="&DATE(2026,7,1),'GL Extract'!$B$4:$B$943,"<"&DATE(2026,8,1))) -> 0 | I14: =1*(SUMIFS('GL Extract'!$I$4:$I$943,'GL Extract'!$C$4:$C$943,"6550",'GL Extract'!$B$4:$B$943,">="&DATE(2026,8,1),'GL Extract'!$B$4:$B$943,"<"&DATE(2026,9,1))) -> 0 | J14: =1*(SUMIFS('GL Extract'!$I$4:$I$943,'GL Extract'!$C$4:$C$943,"6550",'GL Extract'!$B$4:$B$943,">="&DATE(2026,9,1),'GL Extract'!$B$4:$B$943,"<"&DATE(2026,10,1))+SUMIF('Adjustment Journals'!$C$4:$C$17,"6550",'Adjustment Journals'!$H$4:$H$17)) -> -24000 | K14: =SUM(B14:J14) -> 72000 | L14: =Budget!K12 -> 72000 | M14: =K14-L14 -> 0 | N14: =IFERROR(M14/L14,0) -> 0
A15: Software & IT | B15: =1*(SUMIFS('GL Extract'!$I$4:$I$943,'GL Extract'!$C$4:$C$943,"6600",'GL Extract'!$B$4:$B$943,">="&DATE(2026,1,1),'GL Extract'!$B$4:$B$943,"<"&DATE(2026,2,1))) -> 23800 | C15: =1*(SUMIFS('GL Extract'!$I$4:$I$943,'GL Extract'!$C$4:$C$943,"6600",'GL Extract'!$B$4:$B$943,">="&DATE(2026,2,1),'GL Extract'!$B$4:$B$943,"<"&DATE(2026,3,1))) -> 25600 | D15: =1*(SUMIFS('GL Extract'!$I$4:$I$943,'GL Extract'!$C$4:$C$943,"6600",'GL Extract'!$B$4:$B$943,">="&DATE(2026,3,1),'GL Extract'!$B$4:$B$943,"<"&DATE(2026,4,1))) -> 22000 | E15: =1*(SUMIFS('GL Extract'!$I$4:$I$943,'GL Extract'!$C$4:$C$943,"6600",'GL Extract'!$B$4:$B$943,">="&DATE(2026,4,1),'GL Extract'!$B$4:$B$943,"<"&DATE(2026,5,1))) -> 23800 | F15: =1*(SUMIFS('GL Extract'!$I$4:$I$943,'GL Extract'!$C$4:$C$943,"6600",'GL Extract'!$B$4:$B$943,">="&DATE(2026,5,1),'GL Extract'!$B$4:$B$943,"<"&DATE(2026,6,1))) -> 25600 | G15: =1*(SUMIFS('GL Extract'!$I$4:$I$943,'GL Extract'!$C$4:$C$943,"6600",'GL Extract'!$B$4:$B$943,">="&DATE(2026,6,1),'GL Extract'!$B$4:$B$943,"<"&DATE(2026,7,1))) -> 22000 | H15: =1*(SUMIFS('GL Extract'!$I$4:$I$943,'GL Extract'!$C$4:$C$943,"6600",'GL Extract'!$B$4:$B$943,">="&DATE(2026,7,1),'GL Extract'!$B$4:$B$943,"<"&DATE(2026,8,1))) -> 23800 | I15: =1*(SUMIFS('GL Extract'!$I$4:$I$943,'GL Extract'!$C$4:$C$943,"6600",'GL Extract'!$B$4:$B$943,">="&DATE(2026,8,1),'GL Extract'!$B$4:$B$943,"<"&DATE(2026,9,1))) -> 25600 | J15: =1*(SUMIFS('GL Extract'!$I$4:$I$943,'GL Extract'!$C$4:$C$943,"6600",'GL Extract'!$B$4:$B$943,">="&DATE(2026,9,1),'GL Extract'!$B$4:$B$943,"<"&DATE(2026,10,1))+SUMIF('Adjustment Journals'!$C$4:$C$17,"6600",'Adjustment Journals'!$H$4:$H$17)) -> 22000 | K15: =SUM(B15:J15) -> 214200 | L15: =Budget!K13 -> 207000 | M15: =K15-L15 -> 7200 | N15: =IFERROR(M15/L15,0) -> 0.034782609
A16: Travel | B16: =1*(SUMIFS('GL Extract'!$I$4:$I$943,'GL Extract'!$C$4:$C$943,"6700",'GL Extract'!$B$4:$B$943,">="&DATE(2026,1,1),'GL Extract'!$B$4:$B$943,"<"&DATE(2026,2,1))) -> 7868.4976 | C16: =1*(SUMIFS('GL Extract'!$I$4:$I$943,'GL Extract'!$C$4:$C$943,"6700",'GL Extract'!$B$4:$B$943,">="&DATE(2026,2,1),'GL Extract'!$B$4:$B$943,"<"&DATE(2026,3,1))) -> 8621.2821 | D16: =1*(SUMIFS('GL Extract'!$I$4:$I$943,'GL Extract'!$C$4:$C$943,"6700",'GL Extract'!$B$4:$B$943,">="&DATE(2026,3,1),'GL Extract'!$B$4:$B$943,"<"&DATE(2026,4,1))) -> 8736.824 | E16: =1*(SUMIFS('GL Extract'!$I$4:$I$943,'GL Extract'!$C$4:$C$943,"6700",'GL Extract'!$B$4:$B$943,">="&DATE(2026,4,1),'GL Extract'!$B$4:$B$943,"<"&DATE(2026,5,1))) -> 7590.5358 | F16: =1*(SUMIFS('GL Extract'!$I$4:$I$943,'GL Extract'!$C$4:$C$943,"6700",'GL Extract'!$B$4:$B$943,">="&DATE(2026,5,1),'GL Extract'!$B$4:$B$943,"<"&DATE(2026,6,1))) -> 8709.5964 | G16: =1*(SUMIFS('GL Extract'!$I$4:$I$943,'GL Extract'!$C$4:$C$943,"6700",'GL Extract'!$B$4:$B$943,">="&DATE(2026,6,1),'GL Extract'!$B$4:$B$943,"<"&DATE(2026,7,1))) -> 10261.467 | H16: =1*(SUMIFS('GL Extract'!$I$4:$I$943,'GL Extract'!$C$4:$C$943,"6700",'GL Extract'!$B$4:$B$943,">="&DATE(2026,7,1),'GL Extract'!$B$4:$B$943,"<"&DATE(2026,8,1))) -> 8260.8632 | I16: =1*(SUMIFS('GL Extract'!$I$4:$I$943,'GL Extract'!$C$4:$C$943,"6700",'GL Extract'!$B$4:$B$943,">="&DATE(2026,8,1),'GL Extract'!$B$4:$B$943,"<"&DATE(2026,9,1))) -> 11150.296 | J16: =1*(SUMIFS('GL Extract'!$I$4:$I$943,'GL Extract'!$C$4:$C$943,"6700",'GL Extract'!$B$4:$B$943,">="&DATE(2026,9,1),'GL Extract'!$B$4:$B$943,"<"&DATE(2026,10,1))+SUMIF('Adjustment Journals'!$C$4:$C$17,"6700",'Adjustment Journals'!$H$4:$H$17)) -> 11555.123 | K16: =SUM(B16:J16) -> 82754.485 | L16: =Budget!K14 -> 81000 | M16: =K16-L16 -> 1754.4847 | N16: =IFERROR(M16/L16,0) -> 0.021660305
A17: Total Opex pre-D&A | B17: =SUM(B8:B16) -> 482187.97 | C17: =SUM(C8:C16) -> 391838.13 | D17: =SUM(D8:D16) -> 389433.86 | E17: =SUM(E8:E16) -> 394094.07 | F17: =SUM(F8:F16) -> 399853.1 | G17: =SUM(G8:G16) -> 409632.69 | H17: =SUM(H8:H16) -> 404065.65 | I17: =SUM(I8:I16) -> 419267.77 | J17: =SUM(J8:J16) -> 458601.69 | K17: =SUM(B17:J17) -> 3748974.9 | L17: =SUM(L8:L16) -> 3675610 | M17: =K17-L17 -> 73364.937 | N17: =IFERROR(M17/L17,0) -> 0.019959935
A18: EBITDA | B18: =B6-B17 -> -117287.97 | C18: =C6-C17 -> -14123.132 | D18: =D6-D17 -> 2566.1378 | E18: =E6-E17 -> 10905.935 | F18: =F6-F17 -> 20506.903 | G18: =G6-G17 -> 21072.307 | H18: =H6-H17 -> 35344.347 | I18: =I6-I17 -> 30192.228 | J18: =J6-J17 -> 3223.3062 | K18: =SUM(B18:J18) -> -7599.9369 | L18: =L6-L17 -> 27890 | M18: =K18-L18 -> -35489.937 | N18: =IFERROR(M18/L18,0) -> -1.2724968
A19: EBITDA Margin % | B19: =IFERROR(B18/B4,0) -> -0.14303411 | C19: =IFERROR(C18/C4,0) -> -0.016713766 | D19: =IFERROR(D18/D4,0) -> 0.0029327289 | E19: =IFERROR(E18/E4,0) -> 0.012117705 | F19: =IFERROR(F18/F4,0) -> 0.022050433 | G19: =IFERROR(G18/G4,0) -> 0.022065243 | H19: =IFERROR(H18/H4,0) -> 0.036437471 | I19: =IFERROR(I18/I4,0) -> 0.0304972 | ... L19: =IFERROR(L18/L4,0) -> 0.0033888214 | M19: =K19-L19 -> -0.0043044764 | N19: -
A20: Depreciation | B20: =1*(SUMIFS('GL Extract'!$I$4:$I$943,'GL Extract'!$C$4:$C$943,"6800",'GL Extract'!$B$4:$B$943,">="&DATE(2026,1,1),'GL Extract'!$B$4:$B$943,"<"&DATE(2026,2,1))) -> 15000 | C20: =1*(SUMIFS('GL Extract'!$I$4:$I$943,'GL Extract'!$C$4:$C$943,"6800",'GL Extract'!$B$4:$B$943,">="&DATE(2026,2,1),'GL Extract'!$B$4:$B$943,"<"&DATE(2026,3,1))) -> 15000 | D20: =1*(SUMIFS('GL Extract'!$I$4:$I$943,'GL Extract'!$C$4:$C$943,"6800",'GL Extract'!$B$4:$B$943,">="&DATE(2026,3,1),'GL Extract'!$B$4:$B$943,"<"&DATE(2026,4,1))) -> 15000 | E20: =1*(SUMIFS('GL Extract'!$I$4:$I$943,'GL Extract'!$C$4:$C$943,"6800",'GL Extract'!$B$4:$B$943,">="&DATE(2026,4,1),'GL Extract'!$B$4:$B$943,"<"&DATE(2026,5,1))) -> 15000 | F20: =1*(SUMIFS('GL Extract'!$I$4:$I$943,'GL Extract'!$C$4:$C$943,"6800",'GL Extract'!$B$4:$B$943,">="&DATE(2026,5,1),'GL Extract'!$B$4:$B$943,"<"&DATE(2026,6,1))) -> 15000 | G20: =1*(SUMIFS('GL Extract'!$I$4:$I$943,'GL Extract'!$C$4:$C$943,"6800",'GL Extract'!$B$4:$B$943,">="&DATE(2026,6,1),'GL Extract'!$B$4:$B$943,"<"&DATE(2026,7,1))) -> 15000 | H20: =1*(SUMIFS('GL Extract'!$I$4:$I$943,'GL Extract'!$C$4:$C$943,"6800",'GL Extract'!$B$4:$B$943,">="&DATE(2026,7,1),'GL Extract'!$B$4:$B$943,"<"&DATE(2026,8,1))) -> 15000 | I20: =1*(SUMIFS('GL Extract'!$I$4:$I$943,'GL Extract'!$C$4:$C$943,"6800",'GL Extract'!$B$4:$B$943,">="&DATE(2026,8,1),'GL Extract'!$B$4:$B$943,"<"&DATE(2026,9,1))) -> 15000 | J20: =1*(SUMIFS('GL Extract'!$I$4:$I$943,'GL Extract'!$C$4:$C$943,"6800",'GL Extract'!$B$4:$B$943,">="&DATE(2026,9,1),'GL Extract'!$B$4:$B$943,"<"&DATE(2026,10,1))+SUMIF('Adjustment Journals'!$C$4:$C$17,"6800",'Adjustment Journals'!$H$4:$H$17)) -> 15000 | K20: =SUM(B20:J20) -> 135000 | L20: =Budget!K15 -> 135000 | M20: =K20-L20 -> 0 | N20: =IFERROR(M20/L20,0) -> 0
A21: Bad Debt | B21: =1*(SUMIFS('GL Extract'!$I$4:$I$943,'GL Extract'!$C$4:$C$943,"6900",'GL Extract'!$B$4:$B$943,">="&DATE(2026,1,1),'GL Extract'!$B$4:$B$943,"<"&DATE(2026,2,1))) -> 0 | C21: =1*(SUMIFS('GL Extract'!$I$4:$I$943,'GL Extract'!$C$4:$C$943,"6900",'GL Extract'!$B$4:$B$943,">="&DATE(2026,2,1),'GL Extract'!$B$4:$B$943,"<"&DATE(2026,3,1))) -> 0 | D21: =1*(SUMIFS('GL Extract'!$I$4:$I$943,'GL Extract'!$C$4:$C$943,"6900",'GL Extract'!$B$4:$B$943,">="&DATE(2026,3,1),'GL Extract'!$B$4:$B$943,"<"&DATE(2026,4,1))) -> 0 | E21: =1*(SUMIFS('GL Extract'!$I$4:$I$943,'GL Extract'!$C$4:$C$943,"6900",'GL Extract'!$B$4:$B$943,">="&DATE(2026,4,1),'GL Extract'!$B$4:$B$943,"<"&DATE(2026,5,1))) -> 0 | F21: =1*(SUMIFS('GL Extract'!$I$4:$I$943,'GL Extract'!$C$4:$C$943,"6900",'GL Extract'!$B$4:$B$943,">="&DATE(2026,5,1),'GL Extract'!$B$4:$B$943,"<"&DATE(2026,6,1))) -> 0 | G21: =1*(SUMIFS('GL Extract'!$I$4:$I$943,'GL Extract'!$C$4:$C$943,"6900",'GL Extract'!$B$4:$B$943,">="&DATE(2026,6,1),'GL Extract'!$B$4:$B$943,"<"&DATE(2026,7,1))) -> 0 | H21: =1*(SUMIFS('GL Extract'!$I$4:$I$943,'GL Extract'!$C$4:$C$943,"6900",'GL Extract'!$B$4:$B$943,">="&DATE(2026,7,1),'GL Extract'!$B$4:$B$943,"<"&DATE(2026,8,1))) -> 0 | I21: =1*(SUMIFS('GL Extract'!$I$4:$I$943,'GL Extract'!$C$4:$C$943,"6900",'GL Extract'!$B$4:$B$943,">="&DATE(2026,8,1),'GL Extract'!$B$4:$B$943,"<"&DATE(2026,9,1))) -> 0 | J21: =1*(SUMIFS('GL Extract'!$I$4:$I$943,'GL Extract'!$C$4:$C$943,"6900",'GL Extract'!$B$4:$B$943,">="&DATE(2026,9,1),'GL Extract'!$B$4:$B$943,"<"&DATE(2026,10,1))+SUMIF('Adjustment Journals'!$C$4:$C$17,"6900",'Adjustment Journals'!$H$4:$H$17)) -> 5000 | K21: =SUM(B21:J21) -> 5000 | L21: =Budget!K16 -> 27000 | M21: =K21-L21 -> -22000 | N21: =IFERROR(M21/L21,0) -> -0.81481481
A22: Operating Profit | B22: =B18-B20-B21 -> -132287.97 | C22: =C18-C20-C21 -> -29123.132 | D22: =D18-D20-D21 -> -12433.862 | E22: =E18-E20-E21 -> -4094.0653 | F22: =F18-F20-F21 -> 5506.9031 | G22: =G18-G20-G21 -> 6072.3068 | H22: =H18-H20-H21 -> 20344.347 | I22: =I18-I20-I21 -> 15192.228 | J22: =J18-J20-J21 -> -16776.694 | K22: =SUM(B22:J22) -> -147599.94 | L22: =L18-L20-L21 -> -134110 | M22: =K22-L22 -> -13489.937 | N22: =IFERROR(M22/L22,0) -> 0.1005886
A23: Interest | B23: =1*(SUMIFS('GL Extract'!$I$4:$I$943,'GL Extract'!$C$4:$C$943,"7000",'GL Extract'!$B$4:$B$943,">="&DATE(2026,1,1),'GL Extract'!$B$4:$B$943,"<"&DATE(2026,2,1))) -> 5500 | C23: =1*(SUMIFS('GL Extract'!$I$4:$I$943,'GL Extract'!$C$4:$C$943,"7000",'GL Extract'!$B$4:$B$943,">="&DATE(2026,2,1),'GL Extract'!$B$4:$B$943,"<"&DATE(2026,3,1))) -> 5500 | D23: =1*(SUMIFS('GL Extract'!$I$4:$I$943,'GL Extract'!$C$4:$C$943,"7000",'GL Extract'!$B$4:$B$943,">="&DATE(2026,3,1),'GL Extract'!$B$4:$B$943,"<"&DATE(2026,4,1))) -> 5500 | E23: =1*(SUMIFS('GL Extract'!$I$4:$I$943,'GL Extract'!$C$4:$C$943,"7000",'GL Extract'!$B$4:$B$943,">="&DATE(2026,4,1),'GL Extract'!$B$4:$B$943,"<"&DATE(2026,5,1))) -> 5500 | F23: =1*(SUMIFS('GL Extract'!$I$4:$I$943,'GL Extract'!$C$4:$C$943,"7000",'GL Extract'!$B$4:$B$943,">="&DATE(2026,5,1),'GL Extract'!$B$4:$B$943,"<"&DATE(2026,6,1))) -> 5500 | G23: =1*(SUMIFS('GL Extract'!$I$4:$I$943,'GL Extract'!$C$4:$C$943,"7000",'GL Extract'!$B$4:$B$943,">="&DATE(2026,6,1),'GL Extract'!$B$4:$B$943,"<"&DATE(2026,7,1))) -> 5500 | H23: =1*(SUMIFS('GL Extract'!$I$4:$I$943,'GL Extract'!$C$4:$C$943,"7000",'GL Extract'!$B$4:$B$943,">="&DATE(2026,7,1),'GL Extract'!$B$4:$B$943,"<"&DATE(2026,8,1))) -> 5500 | I23: =1*(SUMIFS('GL Extract'!$I$4:$I$943,'GL Extract'!$C$4:$C$943,"7000",'GL Extract'!$B$4:$B$943,">="&DATE(2026,8,1),'GL Extract'!$B$4:$B$943,"<"&DATE(2026,9,1))) -> 5500 | J23: =1*(SUMIFS('GL Extract'!$I$4:$I$943,'GL Extract'!$C$4:$C$943,"7000",'GL Extract'!$B$4:$B$943,">="&DATE(2026,9,1),'GL Extract'!$B$4:$B$943,"<"&DATE(2026,10,1))+SUMIF('Adjustment Journals'!$C$4:$C$17,"7000",'Adjustment Journals'!$H$4:$H$17)) -> 5500 | K23: =SUM(B23:J23) -> 49500 | L23: =Budget!K17 -> 49500 | M23: =K23-L23 -> 0 | N23: =IFERROR(M23/L23,0) -> 0
A24: Profit Before Tax | B24: =B22-B23 -> -137787.97 | C24: =C22-C23 -> -34623.132 | D24: =D22-D23 -> -17933.862 | E24: =E22-E23 -> -9594.0653 | F24: =F22-F23 -> 6.9030805 | G24: =G22-G23 -> 572.30678 | H24: =H22-H23 -> 14844.347 | I24: =I22-I23 -> 9692.2284 | J24: =J22-J23 -> -22276.694 | K24: =SUM(B24:J24) -> -197099.94 | L24: =L22-L23 -> -183610 | M24: =K24-L24 -> -13489.937 | N24: =IFERROR(M24/L24,0) -> 0.0734706

Sheet Balance Sheet
A1: Balance Sheet — 30 Sep 2026
A3: Balance Sheet Line | B3: Opening (£) | C3: Sep Closing (£) | D3: Movement (£)
A4: Cash | B4: =1*SUMIF('Opening TB'!$A$4:$A$30,"1000",'Opening TB'!$C$4:$C$30) -> 450000 | C4: =1*SUMIF('Adjusted TB'!$A$4:$A$30,"1000",'Adjusted TB'!$H$4:$H$30) -> 857522.22 | D4: =C4-B4 -> 407522.22
A5: Trade Receivables | B5: =1*SUMIF('Opening TB'!$A$4:$A$30,"1100",'Opening TB'!$C$4:$C$30) -> 800000 | C5: =1*SUMIF('Adjusted TB'!$A$4:$A$30,"1100",'Adjusted TB'!$H$4:$H$30) -> 1151225 | D5: =C5-B5 -> 351225
A6: Allowance for Doubtful Debts | B6: =-1*SUMIF('Opening TB'!$A$4:$A$30,"1150",'Opening TB'!$C$4:$C$30) -> 30000 | C6: =-1*SUMIF('Adjusted TB'!$A$4:$A$30,"1150",'Adjusted TB'!$H$4:$H$30) -> 35000 | D6: =C6-B6 -> 5000
A7: Inventory | B7: =1*SUMIF('Opening TB'!$A$4:$A$30,"1200",'Opening TB'!$C$4:$C$30) -> 650000 | C7: =1*SUMIF('Adjusted TB'!$A$4:$A$30,"1200",'Adjusted TB'!$H$4:$H$30) -> 660084.8 | D7: =C7-B7 -> 10084.8
A8: Prepayments | B8: =1*SUMIF('Opening TB'!$A$4:$A$30,"1300",'Opening TB'!$C$4:$C$30) -> 90000 | C8: =1*SUMIF('Adjusted TB'!$A$4:$A$30,"1300",'Adjusted TB'!$H$4:$H$30) -> 114000 | D8: =C8-B8 -> 24000
A9: Property, Plant & Equipment | B9: =1*SUMIF('Opening TB'!$A$4:$A$30,"1400",'Opening TB'!$C$4:$C$30) -> 1200000 | C9: =1*SUMIF('Adjusted TB'!$A$4:$A$30,"1400",'Adjusted TB'!$H$4:$H$30) -> 1430000 | D9: =C9-B9 -> 230000
A10: Accumulated Depreciation | B10: =-1*SUMIF('Opening TB'!$A$4:$A$30,"1450",'Opening TB'!$C$4:$C$30) -> 350000 | C10: =-1*SUMIF('Adjusted TB'!$A$4:$A$30,"1450",'Adjusted TB'!$H$4:$H$30) -> 485000 | D10: =C10-B10 -> 135000
A11: Trade Payables | B11: =-1*SUMIF('Opening TB'!$A$4:$A$30,"2000",'Opening TB'!$C$4:$C$30) -> 600000 | C11: =-1*SUMIF('Adjusted TB'!$A$4:$A$30,"2000",'Adjusted TB'!$H$4:$H$30) -> 1639932 | D11: =C11-B11 -> 1039932
A12: Accrued Expenses | B12: =-1*SUMIF('Opening TB'!$A$4:$A$30,"2100",'Opening TB'!$C$4:$C$30) -> 150000 | C12: =-1*SUMIF('Adjusted TB'!$A$4:$A$30,"2100",'Adjusted TB'!$H$4:$H$30) -> 255000 | D12: =C12-B12 -> 105000
A13: Payroll Liabilities | B13: =-1*SUMIF('Opening TB'!$A$4:$A$30,"2200",'Opening TB'!$C$4:$C$30) -> 60000 | C13: =-1*SUMIF('Adjusted TB'!$A$4:$A$30,"2200",'Adjusted TB'!$H$4:$H$30) -> 60000 | D13: =C13-B13 -> 0
A14: Tax Payable | B14: =-1*SUMIF('Opening TB'!$A$4:$A$30,"2300",'Opening TB'!$C$4:$C$30) -> 100000 | C14: =-1*SUMIF('Adjusted TB'!$A$4:$A$30,"2300",'Adjusted TB'!$H$4:$H$30) -> 35000 | D14: =C14-B14 -> -65000
A15: Share Capital | B15: =-1*SUMIF('Opening TB'!$A$4:$A$30,"3000",'Opening TB'!$C$4:$C$30) -> 500000 | C15: =-1*SUMIF('Adjusted TB'!$A$4:$A$30,"3000",'Adjusted TB'!$H$4:$H$30) -> 500000 | D15: =C15-B15 -> 0
A16: Retained Earnings | B16: =-1*SUMIF('Opening TB'!$A$4:$A$30,"3100",'Opening TB'!$C$4:$C$30) -> 1400000 | C16: =-1*SUMIF('Adjusted TB'!$A$4:$A$30,"3100",'Adjusted TB'!$H$4:$H$30) -> 1400000 | D16: =C16-B16 -> 0
A19: Balance Sheet Summary
A20: Metric | B20: Sep Closing (£)
A21: Total Current Assets | B21: =C4+C5-C6+C7+C8 -> 2747832
A22: Net PP&E | B22: =C9-C10 -> 945000
A23: Total Assets | B23: =B21+B22 -> 3692832
A24: Total Current Liabilities | B24: =SUM(C11:C14) -> 1989932
A25: Total Equity incl. YTD PBT | B25: =SUM(C15:C16)+'Management P&L'!K24 -> 1702900.1
A26: Liabilities + Equity | B26: =B24+B25 -> 3692832
A27: Balance Check | B27: =B23-B26 -> 0

Sheet Bank Reconciliation
A1: Bank Reconciliation — 30 Sep 2026
A3: Outstanding reconciling items
A4: Item | B4: Type | C4: Amount (£) | D4: Source
A5: Deposit in transit 1 | B5: Outstanding deposit | C5: 8500 | D5: Synthetic bank reconciliation
A6: Deposit in transit 2 | B6: Outstanding deposit | C6: 7200 | D6: Synthetic bank reconciliation
A7: Deposit in transit 3 | B7: Outstanding deposit | C7: 6300 | D7: Synthetic bank reconciliation
A8: Unpresented payments | B8: Payment schedule | C8: 17000 | D8: Synthetic bank reconciliation
A11: Reconciliation | B11: Amount (£)
A12: Bank Statement Balance | B12: 852522.22
A13: Add: Deposits in Transit | B13: =SUM(C5:C7) -> 22000
A14: Less: Unpresented Payments | B14: =C8 -> 17000
A15: Adjusted Bank Balance | B15: =B12+B13-B14 -> 857522.22
A16: GL Bank Balance | B16: =SUMIF('Adjusted TB'!$A$4:$A$30,"1000",'Adjusted TB'!$H$4:$H$30) -> 857522.22
A17: Difference | B17: =B15-B16 -> 0

Sheet AR Ageing
A1: Accounts Receivable Ageing — 30 Sep 2026
A3: Invoice ID | B3: Customer | C3: Invoice Date | D3: Due Date | E3: Outstanding (£) | F3: Days Overdue | G3: Age Bucket | H3: Expected Credit Loss % | I3: ECL (£) | J3: Collection Priority | K3: Source
A4: AR0001 | B4: Customer 03 | C4: 46207 | D4: 46237 | E4: 14039.078 | F4: =DATE(2026,9,30)-D4 -> 58 | G4: =IF(F4<=0,"Current",IF(F4<=30,"1-30",IF(F4<=60,"31-60",IF(F4<=90,"61-90","90+")))) -> 31-60 | H4: =IF(G4="Current",0.5%,IF(G4="1-30",1%,IF(G4="31-60",3%,IF(G4="61-90",10%,25%)))) -> 0.03 | I4: =E4*H4 -> 421.17234 | J4: =IF(F4>90,"Escalate",IF(F4>30,"Chase","Routine")) -> Chase | K4: Synthetic AR ledger
A5: AR0002 | B5: Customer 26 | C5: 46272 | D5: 46302 | E5: 31470.479 | F5: =DATE(2026,9,30)-D5 -> -7 | G5: =IF(F5<=0,"Current",IF(F5<=30,"1-30",IF(F5<=60,"31-60",IF(F5<=90,"61-90","90+")))) -> Current | H5: =IF(G5="Current",0.5%,IF(G5="1-30",1%,IF(G5="31-60",3%,IF(G5="61-90",10%,25%)))) -> 0.005 | I5: =E5*H5 -> 157.35239 | J5: =IF(F5>90,"Escalate",IF(F5>30,"Chase","Routine")) -> Routine | K5: Synthetic AR ledger
A6: AR0003 | B6: Customer 06 | C6: 46266 | D6: 46296 | E6: 7983.4549 | F6: =DATE(2026,9,30)-D6 -> -1 | G6: =IF(F6<=0,"Current",IF(F6<=30,"1-30",IF(F6<=60,"31-60",IF(F6<=90,"61-90","90+")))) -> Current | H6: =IF(G6="Current",0.5%,IF(G6="1-30",1%,IF(G6="31-60",3%,IF(G6="61-90",10%,25%)))) -> 0.005 | I6: =E6*H6 -> 39.917275 | J6: =IF(F6>90,"Escalate",IF(F6>30,"Chase","Routine")) -> Routine | K6: Synthetic AR ledger
A7: AR0004 | B7: Customer 28 | C7: 46182 | D7: 46212 | E7: 15628.995 | F7: =DATE(2026,9,30)-D7 -> 83 | G7: =IF(F7<=0,"Current",IF(F7<=30,"1-30",IF(F7<=60,"31-60",IF(F7<=90,"61-90","90+")))) -> 61-90 | H7: =IF(G7="Current",0.5%,IF(G7="1-30",1%,IF(G7="31-60",3%,IF(G7="61-90",10%,25%)))) -> 0.1 | I7: =E7*H7 -> 1562.8995 | J7: =IF(F7>90,"Escalate",IF(F7>30,"Chase","Routine")) -> Chase | K7: Synthetic AR ledger
A8: AR0005 | B8: Customer 10 | C8: 46274 | D8: 46304 | E8: 15869.442 | F8: =DATE(2026,9,30)-D8 -> -9 | G8: =IF(F8<=0,"Current",IF(F8<=30,"1-30",IF(F8<=60,"31-60",IF(F8<=90,"61-90","90+")))) -> Current | H8: =IF(G8="Current",0.5%,IF(G8="1-30",1%,IF(G8="31-60",3%,IF(G8="61-90",10%,25%)))) -> 0.005 | I8: =E8*H8 -> 79.347212 | J8: =IF(F8>90,"Escalate",IF(F8>30,"Chase","Routine")) -> Routine | K8: Synthetic AR ledger
