Workbook

Sheet README
A1: Project 3 — FINAL Portfolio Release
A3: Month-End Management Accounts, Working Capital & 13-Week Cash Forecast
A5: Final architecture
A6: Workbook 1 | B6: Detailed V1 accounting engine: 940-line GL, journals, adjusted TB, management P&L, balance sheet, reconciliations, ageing, working capital and 13-week cash forecast.
A7: Workbook 2 | B7: This FINAL CFO pack: variance investigation, reconciliation review, working-capital actions, cash stress scenarios, CFO commentary and recruiter summary.
A8: Close period | B8: September 2026
A9: Company | B9: Aster & Vale Consumer Products Ltd — fictional UK consumer-products business
A10: Data | B10: 100% synthetic portfolio data
A11: Final close status | B11: 100% simulated completion after review/sign-off
A12: Portfolio use | B12: CV, LinkedIn, interviews, GitHub/portfolio and finance-role applications
A15: Integrity statement
A16: All company data, invoices, journals, forecasts and quantified opportunities are synthetic. Working-capital releases and cash scenarios are modelled planning outputs—not realised savings. The project demonstrates accounting logic, financial control, management reporting and decision support.

Sheet Source Inputs
A1: Linked Source Outputs from Project 3 V1
A3: Blue hardcodes below are extracted from the reconciled V1 workbook and feed the FINAL management layer.
A5: Management P&L | F5: Balance sheet / controls
A6: Metric | B6: Value | C6: Unit | D6: V1 Source | F6: Metric | G6: Value | H6: Unit | I6: V1 Source
A7: YTD Revenue | B7: 8300000 | C7: £ | D7: Management P&L | F7: Closing Cash | G7: 857522.22 | H7: £ | I7: Balance Sheet
A8: YTD Revenue Budget | B8: 8230000 | C8: £ | D8: Budget | F8: Trade Receivables | G8: 1151225 | H8: £ | I8: AR Ageing
A9: YTD Gross Profit | B9: 3741375 | C9: £ | D9: Management P&L | F9: Allowance for Doubtful Debts | G9: 35000 | H9: £ | I9: Adjusted TB
A10: YTD Gross Profit Budget | B10: 3703500 | C10: £ | D10: Budget | F10: Inventory | G10: 660084.8 | H10: £ | I10: Balance Sheet
A11: YTD Gross Margin | B11: 0.45076807 | C11: % | D11: Management P&L | F11: Prepayments | G11: 114000 | H11: £ | I11: Balance Sheet
A12: YTD Gross Margin Budget | B12: 0.45 | C12: % | D12: Budget | F12: Net PP&E | G12: 945000 | H12: £ | I12: Balance Sheet
A13: YTD Salaries | B13: 1709430.3 | C13: £ | D13: Management P&L | F13: Trade Payables | G13: 1639932 | H13: £ | I13: AP Ageing
A14: YTD Salaries Budget | B14: 1666000 | C14: £ | D14: Budget | F14: Accrued Expenses | G14: 255000 | H14: £ | I14: Adjusted TB
A15: YTD Marketing | B15: 648420.63 | C15: £ | D15: Management P&L | F15: Payroll Liabilities | G15: 60000 | H15: £ | I15: Adjusted TB
A16: YTD Marketing Budget | B16: 619200 | C16: £ | D16: Budget | F16: Tax Payable | G16: 35000 | H16: £ | I16: Adjusted TB
A17: YTD Utilities | B17: 187761.23 | C17: £ | D17: Management P&L | F17: Balance Sheet Check | G17: 0 | H17: £ | I17: Balance Sheet
A18: YTD Utilities Budget | B18: 190800 | C18: £ | D18: Budget | F18: Bank Rec Difference | G18: 0 | H18: £ | I18: Bank Reconciliation
... A21: YTD Software & IT | B21: 214200 | C21: £ | D21: Management P&L | F21: Modelled ECL | G21: 25758.165 | H21: £ | I21: AR Ageing
A22: YTD Software & IT Budget | B22: 207000 | C22: £ | D22: Budget
A23: YTD Travel | B23: 82754.485 | C23: £ | D23: Management P&L
A24: YTD Travel Budget | B24: 81000 | C24: £ | D24: Budget | F24: Working capital / close
A25: YTD EBITDA | B25: -7599.9369 | C25: £ | D25: Management P&L | F25: Metric | G25: Value | H25: Unit | I25: V1 Source
A26: YTD EBITDA Budget | B26: 27890 | C26: £ | D26: Budget | F26: DSO | G26: 34.026355 | H26: days | I26: Working Capital
A27: YTD PBT | B27: -197099.94 | C27: £ | D27: Management P&L | F27: Inventory Days | G27: 35.797974 | H27: days | I27: Working Capital
A28: YTD PBT Budget | B28: -183610 | C28: £ | D28: Budget | F28: DPO | G28: 88.937422 | H28: days | I28: Working Capital
A29: Sep Revenue | B29: 1015000 | C29: £ | D29: Management P&L | F29: Cash Conversion Cycle | G29: -19.113094 | H29: days | I29: Working Capital
A30: Sep COGS | B30: 553175 | C30: £ | D30: Management P&L | F30: Net Working Capital | G30: 171377.84 | H30: £ | I30: Working Capital
F31: 90+ Day AR % | G31: 0.015102086 | H31: % | I31: AR Ageing
F32: 61-90 Day AR | G32: 93403.796 | H32: £ | I32: AR Ageing
A33: Base 13-week cash forecast inputs | F33: 90+ Day AR | G33: 17385.899 | H33: £ | I33: AR Ageing
A34: Week | B34: Week Start | C34: Customer Receipts £ | D34: Supplier Payments £ | E34: Payroll £ | F34: Rent £ | G34: Other Opex £ | H34: Capex £ | I34: Tax / Interest £
A35: 1 | B35: 46300 | C35: 494374 | D35: 484265.03 | E35: 0 | F35: 52000 | G35: 27000 | H35: 0 | I35: 0
A36: 2 | B36: 46307 | C36: 471349.5 | D36: 451466.39 | E36: 0 | F36: 0 | G36: 27000 | H36: 0 | I36: 0
A37: 3 | B37: 46314 | C37: 425300.5 | D37: 418667.75 | E37: 0 | F37: 0 | G37: 27000 | H37: 0 | I37: 0
A38: 4 | B38: 46321 | C38: 356227 | D38: 353070.47 | E38: 215000 | F38: 0 | G38: 27000 | H38: 0 | I38: 0
A39: 5 | B39: 46328 | C39: 218080 | D39: 123480 | E39: 0 | F39: 52000 | G39: 27000 | H39: 0 | I39: 0
A40: 6 | B40: 46335 | C40: 218080 | D40: 123480 | E40: 0 | F40: 0 | G40: 27000 | H40: 45000 | I40: 0
A41: 7 | B41: 46342 | C41: 218080 | D41: 123480 | E41: 0 | F41: 0 | G41: 27000 | H41: 0 | I41: 0
A42: 8 | B42: 46349 | C42: 218080 | D42: 123480 | E42: 215000 | F42: 0 | G42: 27000 | H42: 0 | I42: 0
A43: 9 | B43: 46356 | C43: 218080 | D43: 123480 | E43: 0 | F43: 52000 | G43: 27000 | H43: 0 | I43: 0
A44: 10 | B44: 46363 | C44: 218080 | D44: 123480 | E44: 0 | F44: 0 | G44: 27000 | H44: 0 | I44: 60000
...

Sheet Variance Investigation
A1: Actual vs Budget Variance Investigation — YTD Sep 2026
A3: Materiality-led review converts the management P&L into specific finance actions.
A5: P&L Line | B5: Actual | C5: Budget | D5: Variance £ | E5: Variance % | F5: Favourability | G5: Materiality | H5: Primary Driver | I5: Interpretation | J5: Action | K5: Owner
A6: Revenue | B6: ='Source Inputs'!B7 -> 8300000 | C6: ='Source Inputs'!B8 -> 8230000 | D6: =B6-C6 -> 70000 | E6: =IFERROR(D6/C6,0) -> 0.0085054678 | F6: =IF(D6>=0,"Favourable","Adverse") -> Favourable | G6: =IF(ABS(D6)>=25000,"High",IF(ABS(D6)>=10000,"Medium","Low")) -> High | H6: Volume and pricing ahead of plan | I6: Top-line performance is ahead of budget. | J6: Protect revenue momentum; monitor mix. | K6: Commercial Finance
A7: Gross Profit | B7: ='Source Inputs'!B9 -> 3741375 | C7: ='Source Inputs'!B10 -> 3703500 | D7: =B7-C7 -> 37875 | E7: =IFERROR(D7/C7,0) -> 0.010226812 | F7: =IF(D7>=0,"Favourable","Adverse") -> Favourable | G7: =IF(ABS(D7)>=25000,"High",IF(ABS(D7)>=10000,"Medium","Low")) -> High | H7: Revenue upside and modest margin outperformance | I7: Gross profit is ahead of plan. | J7: Maintain price/cost discipline. | K7: Finance Business Partner
A8: Gross Margin % | B8: ='Source Inputs'!B11 -> 0.45076807 | C8: ='Source Inputs'!B12 -> 0.45 | D8: =B8-C8 -> 0.00076807229 | E8: - | F8: =IF(D8>=0,"Favourable","Adverse") -> Favourable | G8: =IF(ABS(D8)>=25000,"High",IF(ABS(D8)>=10000,"Medium","Low")) -> Low | H8: Small positive rate variance | I8: Margin rate is slightly above budget. | J8: Monitor price/cost balance. | K8: Commercial Finance
A9: Salaries | B9: ='Source Inputs'!B13 -> 1709430.3 | C9: ='Source Inputs'!B14 -> 1666000 | D9: =B9-C9 -> 43430.304 | E9: =IFERROR(D9/C9,0) -> 0.02606861 | F9: =IF(D9<=0,"Favourable","Adverse") -> Adverse | G9: =IF(ABS(D9)>=25000,"High",IF(ABS(D9)>=10000,"Medium","Low")) -> High | H9: Staffing and Q3 bonus accrual above plan | I9: People costs absorb top-line upside. | J9: Review vacancies, overtime and bonus phasing. | K9: Finance Manager
A10: Marketing | B10: ='Source Inputs'!B15 -> 648420.63 | C10: ='Source Inputs'!B16 -> 619200 | D10: =B10-C10 -> 29220.634 | E10: =IFERROR(D10/C10,0) -> 0.047190947 | F10: =IF(D10<=0,"Favourable","Adverse") -> Adverse | G10: =IF(ABS(D10)>=25000,"High",IF(ABS(D10)>=10000,"Medium","Low")) -> High | H10: Campaign spend and Sep accrual above plan | I10: Marketing is a material adverse variance. | J10: Validate ROI and rephase discretionary spend. | K10: Commercial Director
A11: Utilities | B11: ='Source Inputs'!B17 -> 187761.23 | C11: ='Source Inputs'!B18 -> 190800 | D11: =B11-C11 -> -3038.7693 | E11: =IFERROR(D11/C11,0) -> -0.015926464 | F11: =IF(D11<=0,"Favourable","Adverse") -> Favourable | G11: =IF(ABS(D11)>=25000,"High",IF(ABS(D11)>=10000,"Medium","Low")) -> Low | H11: Spend below plan | I11: Utilities are modestly favourable. | J11: Retain updated run-rate. | K11: Management Accountant
A12: Professional Fees | B12: ='Source Inputs'!B19 -> 140360.19 | C12: ='Source Inputs'!B20 -> 146700 | D12: =B12-C12 -> -6339.8076 | E12: =IFERROR(D12/C12,0) -> -0.043216139 | F12: =IF(D12<=0,"Favourable","Adverse") -> Favourable | G12: =IF(ABS(D12)>=25000,"High",IF(ABS(D12)>=10000,"Medium","Low")) -> Low | H12: Spend below plan | I12: Professional fees are favourable. | J12: Confirm no unbilled commitments remain. | K12: Financial Controller
A13: Software & IT | B13: ='Source Inputs'!B21 -> 214200 | C13: ='Source Inputs'!B22 -> 207000 | D13: =B13-C13 -> 7200 | E13: =IFERROR(D13/C13,0) -> 0.034782609 | F13: =IF(D13<=0,"Favourable","Adverse") -> Adverse | G13: =IF(ABS(D13)>=25000,"High",IF(ABS(D13)>=10000,"Medium","Low")) -> Low | H13: Subscription run-rate above plan | I13: IT spend is modestly adverse. | J13: Review licences and renewals. | K13: Finance Business Partner
A14: Travel | B14: ='Source Inputs'!B23 -> 82754.485 | C14: ='Source Inputs'!B24 -> 81000 | D14: =B14-C14 -> 1754.4847 | E14: =IFERROR(D14/C14,0) -> 0.021660305 | F14: =IF(D14<=0,"Favourable","Adverse") -> Adverse | G14: =IF(ABS(D14)>=25000,"High",IF(ABS(D14)>=10000,"Medium","Low")) -> Low | H14: Activity above plan | I14: Travel is slightly adverse. | J14: Apply approval thresholds. | K14: Finance Manager
A15: EBITDA | B15: ='Source Inputs'!B25 -> -7599.9369 | C15: ='Source Inputs'!B26 -> 27890 | D15: =B15-C15 -> -35489.937 | E15: =IFERROR(D15/C15,0) -> -1.2724968 | F15: =IF(D15>=0,"Favourable","Adverse") -> Adverse | G15: =IF(ABS(D15)>=25000,"High",IF(ABS(D15)>=10000,"Medium","Low")) -> High | H15: Cost overruns exceed gross-profit upside | I15: EBITDA is below budget despite revenue growth. | J15: Prioritise payroll and marketing actions. | K15: CFO
A16: Profit Before Tax | B16: ='Source Inputs'!B27 -> -197099.94 | C16: ='Source Inputs'!B28 -> -183610 | D16: =B16-C16 -> -13489.937 | E16: =IFERROR(D16/C16,0) -> 0.0734706 | F16: =IF(D16>=0,"Favourable","Adverse") -> Adverse | G16: =IF(ABS(D16)>=25000,"High",IF(ABS(D16)>=10000,"Medium","Low")) -> Medium | H16: EBITDA shortfall drives adverse PBT | I16: Bottom-line remains below plan. | J16: Track Q4 corrective actions. | K16: CFO
A19: Executive variance summary
A20: Metric | B20: Value
A21: Revenue Variance | B21: =D6 -> 70000
A22: Gross Profit Variance | B22: =D7 -> 37875
A23: Salary Variance | B23: =D9 -> 43430.304
A24: Marketing Variance | B24: =D10 -> 29220.634
A25: EBITDA Variance | B25: =D15 -> -35489.937

Sheet BS Reconciliation Pack
A1: Balance Sheet Reconciliation Pack — 30 Sep 2026
A3: Core balances reconcile cleanly; allowance is retained as a judgemental review against modelled ECL.
A5: Account | B5: TB Balance £ | C5: Support £ | D5: Difference £ | E5: Status | F5: Support Source | G5: Owner | H5: Review Note | I5: Action | J5: Risk | K5: Evidence | L5: Final Sign-off
A6: Bank | B6: ='Source Inputs'!G7 -> 857522.22 | C6: ='Source Inputs'!G7 -> 857522.22 | D6: =B6-C6 -> 0 | E6: =IF(ABS(D6)<=1,"PASS",IF(A6="Allowance for Doubtful Debts","REVIEW","CHECK")) -> PASS | F6: Bank reconciliation | G6: Financial Accountant | H6: Bank reconciles to statement. | I6: Clear outstanding items in normal course. | J6: Low | K6: V1 Bank Rec | L6: Signed
A7: Trade Receivables | B7: ='Source Inputs'!G8 -> 1151225 | C7: ='Source Inputs'!G8 -> 1151225 | D7: =B7-C7 -> 0 | E7: =IF(ABS(D7)<=1,"PASS",IF(A7="Allowance for Doubtful Debts","REVIEW","CHECK")) -> PASS | F7: AR ageing | G7: Credit Controller | H7: Subledger ties to control account. | I7: Continue aged-debt actions. | J7: Medium | K7: V1 AR Ageing | L7: Signed
A8: Allowance for Doubtful Debts | B8: ='Source Inputs'!G9 -> 35000 | C8: ='Source Inputs'!G21 -> 25758.165 | D8: =B8-C8 -> 9241.835 | E8: =IF(ABS(D8)<=1,"PASS",IF(A8="Allowance for Doubtful Debts","REVIEW","CHECK")) -> REVIEW | F8: ECL model | G8: Finance Manager | H8: Allowance is above modelled ECL; judgement is required. | I8: Document provisioning judgement. | J8: Medium | K8: V1 AR Ageing | L8: Reviewed
A9: Inventory | B9: ='Source Inputs'!G10 -> 660084.8 | C9: ='Source Inputs'!G10 -> 660084.8 | D9: =B9-C9 -> 0 | E9: =IF(ABS(D9)<=1,"PASS",IF(A9="Allowance for Doubtful Debts","REVIEW","CHECK")) -> PASS | F9: Inventory roll-forward | G9: Management Accountant | H9: Ledger balance supported by roll-forward. | I9: Cycle-count/obsolescence review in a real close. | J9: Medium | K9: V1 GL | L9: Signed
A10: Prepayments | B10: ='Source Inputs'!G11 -> 114000 | C10: ='Source Inputs'!G11 -> 114000 | D10: =B10-C10 -> 0 | E10: =IF(ABS(D10)<=1,"PASS",IF(A10="Allowance for Doubtful Debts","REVIEW","CHECK")) -> PASS | F10: Prepayment schedule | G10: Management Accountant | H10: Insurance prepayment supported. | I10: Roll forward monthly amortisation. | J10: Low | K10: V1 Adjustments | L10: Signed
A11: Net PP&E | B11: ='Source Inputs'!G12 -> 945000 | C11: ='Source Inputs'!G12 -> 945000 | D11: =B11-C11 -> 0 | E11: =IF(ABS(D11)<=1,"PASS",IF(A11="Allowance for Doubtful Debts","REVIEW","CHECK")) -> PASS | F11: Fixed asset roll-forward | G11: Management Accountant | H11: Net PP&E supported by capex/depreciation schedules. | I11: Retain capex support. | J11: Low | K11: V1 GL | L11: Signed
A12: Trade Payables | B12: ='Source Inputs'!G13 -> 1639932 | C12: ='Source Inputs'!G13 -> 1639932 | D12: =B12-C12 -> 0 | E12: =IF(ABS(D12)<=1,"PASS",IF(A12="Allowance for Doubtful Debts","REVIEW","CHECK")) -> PASS | F12: AP ageing | G12: AP Lead | H12: Subledger ties to control account. | I12: Prioritise overdue suppliers. | J12: Medium | K12: V1 AP Ageing | L12: Signed
A13: Accrued Expenses | B13: ='Source Inputs'!G14 -> 255000 | C13: ='Source Inputs'!G14 -> 255000 | D13: =B13-C13 -> 0 | E13: =IF(ABS(D13)<=1,"PASS",IF(A13="Allowance for Doubtful Debts","REVIEW","CHECK")) -> PASS | F13: Accrual schedule | G13: Management Accountant | H13: Accruals supported by month-end journals. | I13: Reverse/replace with invoices. | J13: Medium | K13: V1 Adjustments | L13: Signed
A14: Payroll Liabilities | B14: ='Source Inputs'!G15 -> 60000 | C14: ='Source Inputs'!G15 -> 60000 | D14: =B14-C14 -> 0 | E14: =IF(ABS(D14)<=1,"PASS",IF(A14="Allowance for Doubtful Debts","REVIEW","CHECK")) -> PASS | F14: Payroll schedule | G14: Payroll Lead | H14: Recurring payroll liability supported. | I14: Reconcile to provider. | J14: Low | K14: V1 GL | L14: Signed
A15: Tax Payable | B15: ='Source Inputs'!G16 -> 35000 | C15: ='Source Inputs'!G16 -> 35000 | D15: =B15-C15 -> 0 | E15: =IF(ABS(D15)<=1,"PASS",IF(A15="Allowance for Doubtful Debts","REVIEW","CHECK")) -> PASS | F15: Tax schedule | G15: Finance Manager | H15: Closing tax balance supported. | I15: Update for next computation. | J15: Low | K15: V1 GL | L15: Signed
A18: Control conclusion
A19: Metric | B19: Value
A20: PASS Items | B20: =COUNTIF(E6:E15,"PASS") -> 9
A21: REVIEW Items | B21: =COUNTIF(E6:E15,"REVIEW") -> 1
A22: CHECK Items | B22: =COUNTIF(E6:E15,"CHECK") -> 0
A23: Overall Balance Sheet Check | B23: ='Source Inputs'!G17 -> 0

Sheet Working Capital Actions
A1: Working Capital Action Plan — September 2026
A3: Negative CCC is useful, but DPO is unusually high; actions focus on collections and inventory rather than supplier stretching.
A5: Area | B5: Current | C5: Target | D5: Gap | E5: Action | F5: Modelled Cash Effect £ | G5: Timing | H5: Owner | I5: Priority | J5: Risk | K5: KPI | L5: Comment
A6: DSO | B6: ='Source Inputs'!G26 -> 34.026355 | C6: 32 | D6: =B6-C6 -> 2.0263547 | E6: Prioritise 31+ day collections; escalate overdue debt. | F6: =('Source Inputs'!B29/30)*MAX(B6-C6,0) -> 68558.333 | G6: 30 days | H6: Credit Controller | I6: High | J6: Medium | K6: DSO | L6: Planning target.
A7: Inventory Days | B7: ='Source Inputs'!G27 -> 35.797974 | C7: 33 | D7: =B7-C7 -> 2.7979735 | E7: Reduce slow-moving / safety-stock days. | F7: =('Source Inputs'!B30/30)*MAX(B7-C7,0) -> 51592.3 | G7: 60 days | H7: Supply Finance | I7: High | J7: Medium | K7: Inventory Days | L7: Planning target.
A8: DPO | B8: ='Source Inputs'!G28 -> 88.937422 | C8: 80 | D8: =B8-C8 -> 8.9374225 | E8: Normalise very extended payment days while managing cash. | F8: =-('Source Inputs'!B30/30)*MAX(B8-C8,0) -> -164798.62 | G8: 60 days | H8: AP Lead | I8: Medium | J8: Supplier | K8: DPO | L8: Supplier-risk guardrail.
A9: 90+ Day AR % | B9: ='Source Inputs'!G31 -> 0.015102086 | C9: 0.01 | D9: =B9-C9 -> 0.0051020857 | E9: Escalate overdue balances and agree collection dates. | F9: ='Source Inputs'!G33 -> 17385.899 | G9: 30 days | H9: Credit Controller | I9: High | J9: Credit | K9: 90+ AR % | L9: Portfolio has limited 90+ debt.
A10: 61+ Day AR | B10: ='Source Inputs'!G32+'Source Inputs'!G33 -> 110789.69 | C10: 0 | D10: =B10-C10 -> 110789.69 | E10: Collect 50% of 61+ day receivables. | F10: =B10*50% -> 55394.847 | G10: 30 days | H10: Credit Controller | I10: High | J10: Credit | K10: Overdue AR | L10: Modelled scenario, not realised cash.
A13: Modelled cash opportunities
A14: Metric | B14: Value
A15: DSO Release Opportunity | B15: =MAX(F6,0) -> 68558.333
A16: Inventory Release Opportunity | B16: =MAX(F7,0) -> 51592.3
A17: 61+ AR Collection Scenario | B17: =F10 -> 55394.847
A18: Net Opportunity before DPO normalisation | B18: =SUM(B15:B17) -> 175545.48

Sheet Cash Scenarios
A1: 13-Week Cash Scenario Analysis
A3: Stress-tests the V1 cash forecast; Management Action defers capex and improves collection/payment discipline.
A5: Scenario | B5: Receipts Factor | C5: Supplier Payment Factor | D5: Other Opex Factor | E5: Capex Factor | F5: Interpretation
A6: Base | B6: 1 | C6: 1 | D6: 1 | E6: 1 | F6: Existing V1 forecast
A7: Downside | B7: 0.92 | C7: 1 | D7: 1.05 | E7: 1 | F7: Slower collections and modest cost pressure
A8: Severe | B8: 0.85 | C8: 1.02 | D8: 1.1 | E8: 1 | F8: Material collections stress plus supplier/cost pressure
A9: Management Action | B9: 0.97 | C9: 0.98 | D9: 0.98 | E9: 0 | F9: Collection focus, payment scheduling and capex deferral
A10: Policy Floor | B10: 250000 | F10: Minimum cash policy
A13: Week | B13: Week Start | C13: Base Ending Cash | D13: Downside Ending Cash | E13: Severe Ending Cash | F13: Management Action Ending Cash | G13: Policy Floor | H13: Downside Headroom | I13: Severe Headroom
A14: 1 | B14: ='Source Inputs'!B35 -> 46300 | C14: ='Source Inputs'!G7+('Source Inputs'!C35-'Source Inputs'!D35-'Source Inputs'!E35-'Source Inputs'!F35-'Source Inputs'!G35-'Source Inputs'!H35-'Source Inputs'!I35) -> 788631.19 | D14: ='Source Inputs'!G7+('Source Inputs'!C35*$B$7-'Source Inputs'!D35*$C$7-'Source Inputs'!E35-'Source Inputs'!F35-'Source Inputs'!G35*$D$7-'Source Inputs'!H35*$E$7-'Source Inputs'!I35) -> 747731.27 | E14: ='Source Inputs'!G7+('Source Inputs'!C35*$B$8-'Source Inputs'!D35*$C$8-'Source Inputs'!E35-'Source Inputs'!F35-'Source Inputs'!G35*$D$8-'Source Inputs'!H35*$E$8-'Source Inputs'!I35) -> 702089.79 | F14: ='Source Inputs'!G7+('Source Inputs'!C35*$B$9-'Source Inputs'!D35*$C$9-'Source Inputs'!E35-'Source Inputs'!F35-'Source Inputs'!G35*$D$9-'Source Inputs'!H35*$E$9-'Source Inputs'!I35) -> 784025.27 | G14: =$B$10 -> 250000 | H14: =D14-G14 -> 497731.27 | I14: =E14-G14 -> 452089.79
A15: 2 | B15: ='Source Inputs'!B36 -> 46307 | C15: =C14+('Source Inputs'!C36-'Source Inputs'!D36-'Source Inputs'!E36-'Source Inputs'!F36-'Source Inputs'!G36-'Source Inputs'!H36-'Source Inputs'!I36) -> 781514.3 | D15: =D14+('Source Inputs'!C36*$B$7-'Source Inputs'!D36*$C$7-'Source Inputs'!E36-'Source Inputs'!F36-'Source Inputs'!G36*$D$7-'Source Inputs'!H36*$E$7-'Source Inputs'!I36) -> 701556.42 | E15: =E14+('Source Inputs'!C36*$B$8-'Source Inputs'!D36*$C$8-'Source Inputs'!E36-'Source Inputs'!F36-'Source Inputs'!G36*$D$8-'Source Inputs'!H36*$E$8-'Source Inputs'!I36) -> 612541.14 | F15: =F14+('Source Inputs'!C36*$B$9-'Source Inputs'!D36*$C$9-'Source Inputs'!E36-'Source Inputs'!F36-'Source Inputs'!G36*$D$9-'Source Inputs'!H36*$E$9-'Source Inputs'!I36) -> 772337.22 | G15: =$B$10 -> 250000 | H15: =D15-G15 -> 451556.42 | I15: =E15-G15 -> 362541.14
A16: 3 | B16: ='Source Inputs'!B37 -> 46314 | C16: =C15+('Source Inputs'!C37-'Source Inputs'!D37-'Source Inputs'!E37-'Source Inputs'!F37-'Source Inputs'!G37-'Source Inputs'!H37-'Source Inputs'!I37) -> 761147.05 | D16: =D15+('Source Inputs'!C37*$B$7-'Source Inputs'!D37*$C$7-'Source Inputs'!E37-'Source Inputs'!F37-'Source Inputs'!G37*$D$7-'Source Inputs'!H37*$E$7-'Source Inputs'!I37) -> 645815.13 | E16: =E15+('Source Inputs'!C37*$B$8-'Source Inputs'!D37*$C$8-'Source Inputs'!E37-'Source Inputs'!F37-'Source Inputs'!G37*$D$8-'Source Inputs'!H37*$E$8-'Source Inputs'!I37) -> 517305.46 | F16: =F15+('Source Inputs'!C37*$B$9-'Source Inputs'!D37*$C$9-'Source Inputs'!E37-'Source Inputs'!F37-'Source Inputs'!G37*$D$9-'Source Inputs'!H37*$E$9-'Source Inputs'!I37) -> 748124.31 | G16: =$B$10 -> 250000 | H16: =D16-G16 -> 395815.13 | I16: =E16-G16 -> 267305.46
A17: 4 | B17: ='Source Inputs'!B38 -> 46321 | C17: =C16+('Source Inputs'!C38-'Source Inputs'!D38-'Source Inputs'!E38-'Source Inputs'!F38-'Source Inputs'!G38-'Source Inputs'!H38-'Source Inputs'!I38) -> 522303.57 | D17: =D16+('Source Inputs'!C38*$B$7-'Source Inputs'!D38*$C$7-'Source Inputs'!E38-'Source Inputs'!F38-'Source Inputs'!G38*$D$7-'Source Inputs'!H38*$E$7-'Source Inputs'!I38) -> 377123.49 | E17: =E16+('Source Inputs'!C38*$B$8-'Source Inputs'!D38*$C$8-'Source Inputs'!E38-'Source Inputs'!F38-'Source Inputs'!G38*$D$8-'Source Inputs'!H38*$E$8-'Source Inputs'!I38) -> 215266.53 | F17: =F16+('Source Inputs'!C38*$B$9-'Source Inputs'!D38*$C$9-'Source Inputs'!E38-'Source Inputs'!F38-'Source Inputs'!G38*$D$9-'Source Inputs'!H38*$E$9-'Source Inputs'!I38) -> 506195.43 | G17: =$B$10 -> 250000 | H17: =D17-G17 -> 127123.49 | I17: =E17-G17 -> -34733.471
A18: 5 | B18: ='Source Inputs'!B39 -> 46328 | C18: =C17+('Source Inputs'!C39-'Source Inputs'!D39-'Source Inputs'!E39-'Source Inputs'!F39-'Source Inputs'!G39-'Source Inputs'!H39-'Source Inputs'!I39) -> 537903.57 | D18: =D17+('Source Inputs'!C39*$B$7-'Source Inputs'!D39*$C$7-'Source Inputs'!E39-'Source Inputs'!F39-'Source Inputs'!G39*$D$7-'Source Inputs'!H39*$E$7-'Source Inputs'!I39) -> 373927.09 | E18: =E17+('Source Inputs'!C39*$B$8-'Source Inputs'!D39*$C$8-'Source Inputs'!E39-'Source Inputs'!F39-'Source Inputs'!G39*$D$8-'Source Inputs'!H39*$E$8-'Source Inputs'!I39) -> 192984.93 | F18: =F17+('Source Inputs'!C39*$B$9-'Source Inputs'!D39*$C$9-'Source Inputs'!E39-'Source Inputs'!F39-'Source Inputs'!G39*$D$9-'Source Inputs'!H39*$E$9-'Source Inputs'!I39) -> 518262.63 | G18: =$B$10 -> 250000 | H18: =D18-G18 -> 123927.09 | I18: =E18-G18 -> -57015.071
A19: 6 | B19: ='Source Inputs'!B40 -> 46335 | C19: =C18+('Source Inputs'!C40-'Source Inputs'!D40-'Source Inputs'!E40-'Source Inputs'!F40-'Source Inputs'!G40-'Source Inputs'!H40-'Source Inputs'!I40) -> 560503.57 | D19: =D18+('Source Inputs'!C40*$B$7-'Source Inputs'!D40*$C$7-'Source Inputs'!E40-'Source Inputs'!F40-'Source Inputs'!G40*$D$7-'Source Inputs'!H40*$E$7-'Source Inputs'!I40) -> 377730.69 | E19: =E18+('Source Inputs'!C40*$B$8-'Source Inputs'!D40*$C$8-'Source Inputs'!E40-'Source Inputs'!F40-'Source Inputs'!G40*$D$8-'Source Inputs'!H40*$E$8-'Source Inputs'!I40) -> 177703.33 | F19: =F18+('Source Inputs'!C40*$B$9-'Source Inputs'!D40*$C$9-'Source Inputs'!E40-'Source Inputs'!F40-'Source Inputs'!G40*$D$9-'Source Inputs'!H40*$E$9-'Source Inputs'!I40) -> 582329.83 | G19: =$B$10 -> 250000 | H19: =D19-G19 -> 127730.69 | I19: =E19-G19 -> -72296.671
A20: 7 | B20: ='Source Inputs'!B41 -> 46342 | C20: =C19+('Source Inputs'!C41-'Source Inputs'!D41-'Source Inputs'!E41-'Source Inputs'!F41-'Source Inputs'!G41-'Source Inputs'!H41-'Source Inputs'!I41) -> 628103.57 | D20: =D19+('Source Inputs'!C41*$B$7-'Source Inputs'!D41*$C$7-'Source Inputs'!E41-'Source Inputs'!F41-'Source Inputs'!G41*$D$7-'Source Inputs'!H41*$E$7-'Source Inputs'!I41) -> 426534.29 | E20: =E19+('Source Inputs'!C41*$B$8-'Source Inputs'!D41*$C$8-'Source Inputs'!E41-'Source Inputs'!F41-'Source Inputs'!G41*$D$8-'Source Inputs'!H41*$E$8-'Source Inputs'!I41) -> 207421.73 | F20: =F19+('Source Inputs'!C41*$B$9-'Source Inputs'!D41*$C$9-'Source Inputs'!E41-'Source Inputs'!F41-'Source Inputs'!G41*$D$9-'Source Inputs'!H41*$E$9-'Source Inputs'!I41) -> 646397.03 | G20: =$B$10 -> 250000 | H20: =D20-G20 -> 176534.29 | I20: =E20-G20 -> -42578.271
A21: 8 | B21: ='Source Inputs'!B42 -> 46349 | C21: =C20+('Source Inputs'!C42-'Source Inputs'!D42-'Source Inputs'!E42-'Source Inputs'!F42-'Source Inputs'!G42-'Source Inputs'!H42-'Source Inputs'!I42) -> 480703.57 | D21: =D20+('Source Inputs'!C42*$B$7-'Source Inputs'!D42*$C$7-'Source Inputs'!E42-'Source Inputs'!F42-'Source Inputs'!G42*$D$7-'Source Inputs'!H42*$E$7-'Source Inputs'!I42) -> 260337.89 | E21: =E20+('Source Inputs'!C42*$B$8-'Source Inputs'!D42*$C$8-'Source Inputs'!E42-'Source Inputs'!F42-'Source Inputs'!G42*$D$8-'Source Inputs'!H42*$E$8-'Source Inputs'!I42) -> 22140.129 | F21: =F20+('Source Inputs'!C42*$B$9-'Source Inputs'!D42*$C$9-'Source Inputs'!E42-'Source Inputs'!F42-'Source Inputs'!G42*$D$9-'Source Inputs'!H42*$E$9-'Source Inputs'!I42) -> 495464.23 | G21: =$B$10 -> 250000 | H21: =D21-G21 -> 10337.892 | I21: =E21-G21 -> -227859.87
A22: 9 | B22: ='Source Inputs'!B43 -> 46356 | C22: =C21+('Source Inputs'!C43-'Source Inputs'!D43-'Source Inputs'!E43-'Source Inputs'!F43-'Source Inputs'!G43-'Source Inputs'!H43-'Source Inputs'!I43) -> 496303.57 | D22: =D21+('Source Inputs'!C43*$B$7-'Source Inputs'!D43*$C$7-'Source Inputs'!E43-'Source Inputs'!F43-'Source Inputs'!G43*$D$7-'Source Inputs'!H43*$E$7-'Source Inputs'!I43) -> 257141.49 | E22: =E21+('Source Inputs'!C43*$B$8-'Source Inputs'!D43*$C$8-'Source Inputs'!E43-'Source Inputs'!F43-'Source Inputs'!G43*$D$8-'Source Inputs'!H43*$E$8-'Source Inputs'!I43) -> -141.47122 | F22: =F21+('Source Inputs'!C43*$B$9-'Source Inputs'!D43*$C$9-'Source Inputs'!E43-'Source Inputs'!F43-'Source Inputs'!G43*$D$9-'Source Inputs'!H43*$E$9-'Source Inputs'!I43) -> 507531.43 | G22: =$B$10 -> 250000 | H22: =D22-G22 -> 7141.4917 | I22: =E22-G22 -> -250141.47
A23: 10 | B23: ='Source Inputs'!B44 -> 46363 | C23: =C22+('Source Inputs'!C44-'Source Inputs'!D44-'Source Inputs'!E44-'Source Inputs'!F44-'Source Inputs'!G44-'Source Inputs'!H44-'Source Inputs'!I44) -> 503903.57 | D23: =D22+('Source Inputs'!C44*$B$7-'Source Inputs'!D44*$C$7-'Source Inputs'!E44-'Source Inputs'!F44-'Source Inputs'!G44*$D$7-'Source Inputs'!H44*$E$7-'Source Inputs'!I44) -> 245945.09 | E23: =E22+('Source Inputs'!C44*$B$8-'Source Inputs'!D44*$C$8-'Source Inputs'!E44-'Source Inputs'!F44-'Source Inputs'!G44*$D$8-'Source Inputs'!H44*$E$8-'Source Inputs'!I44) -> -30423.071 | F23: =F22+('Source Inputs'!C44*$B$9-'Source Inputs'!D44*$C$9-'Source Inputs'!E44-'Source Inputs'!F44-'Source Inputs'!G44*$D$9-'Source Inputs'!H44*$E$9-'Source Inputs'!I44) -> 511598.63 | G23: =$B$10 -> 250000 | H23: =D23-G23 -> -4054.9083 | I23: =E23-G23 -> -280423.07
A24: 11 | B24: ='Source Inputs'!B45 -> 46370 | C24: =C23+('Source Inputs'!C45-'Source Inputs'!D45-'Source Inputs'!E45-'Source Inputs'!F45-'Source Inputs'!G45-'Source Inputs'!H45-'Source Inputs'!I45) -> 526503.57 | D24: =D23+('Source Inputs'!C45*$B$7-'Source Inputs'!D45*$C$7-'Source Inputs'!E45-'Source Inputs'!F45-'Source Inputs'!G45*$D$7-'Source Inputs'!H45*$E$7-'Source Inputs'!I45) -> 249748.69 | E24: =E23+('Source Inputs'!C45*$B$8-'Source Inputs'!D45*$C$8-'Source Inputs'!E45-'Source Inputs'!F45-'Source Inputs'!G45*$D$8-'Source Inputs'!H45*$E$8-'Source Inputs'!I45) -> -45704.671 | F24: =F23+('Source Inputs'!C45*$B$9-'Source Inputs'!D45*$C$9-'Source Inputs'!E45-'Source Inputs'!F45-'Source Inputs'!G45*$D$9-'Source Inputs'!H45*$E$9-'Source Inputs'!I45) -> 575665.83 | G24: =$B$10 -> 250000 | H24: =D24-G24 -> -251.30827 | I24: =E24-G24 -> -295704.67
A25: 12 | B25: ='Source Inputs'!B46 -> 46377 | C25: =C24+('Source Inputs'!C46-'Source Inputs'!D46-'Source Inputs'!E46-'Source Inputs'!F46-'Source Inputs'!G46-'Source Inputs'!H46-'Source Inputs'!I46) -> 594103.57 | D25: =D24+('Source Inputs'!C46*$B$7-'Source Inputs'!D46*$C$7-'Source Inputs'!E46-'Source Inputs'!F46-'Source Inputs'!G46*$D$7-'Source Inputs'!H46*$E$7-'Source Inputs'!I46) -> 298552.29 | E25: =E24+('Source Inputs'!C46*$B$8-'Source Inputs'!D46*$C$8-'Source Inputs'!E46-'Source Inputs'!F46-'Source Inputs'!G46*$D$8-'Source Inputs'!H46*$E$8-'Source Inputs'!I46) -> -15986.271 | F25: =F24+('Source Inputs'!C46*$B$9-'Source Inputs'!D46*$C$9-'Source Inputs'!E46-'Source Inputs'!F46-'Source Inputs'!G46*$D$9-'Source Inputs'!H46*$E$9-'Source Inputs'!I46) -> 639733.03 | G25: =$B$10 -> 250000 | H25: =D25-G25 -> 48552.292 | I25: =E25-G25 -> -265986.27
A26: 13 | B26: ='Source Inputs'!B47 -> 46384 | C26: =C25+('Source Inputs'!C47-'Source Inputs'!D47-'Source Inputs'!E47-'Source Inputs'!F47-'Source Inputs'!G47-'Source Inputs'!H47-'Source Inputs'!I47) -> 394703.57 | D26: =D25+('Source Inputs'!C47*$B$7-'Source Inputs'!D47*$C$7-'Source Inputs'!E47-'Source Inputs'!F47-'Source Inputs'!G47*$D$7-'Source Inputs'!H47*$E$7-'Source Inputs'!I47) -> 80355.892 | E26: =E25+('Source Inputs'!C47*$B$8-'Source Inputs'!D47*$C$8-'Source Inputs'!E47-'Source Inputs'!F47-'Source Inputs'!G47*$D$8-'Source Inputs'!H47*$E$8-'Source Inputs'!I47) -> -253267.87 | F26: =F25+('Source Inputs'!C47*$B$9-'Source Inputs'!D47*$C$9-'Source Inputs'!E47-'Source Inputs'!F47-'Source Inputs'!G47*$D$9-'Source Inputs'!H47*$E$9-'Source Inputs'!I47) -> 436800.23 | G26: =$B$10 -> 250000 | H26: =D26-G26 -> -169644.11 | I26: =E26-G26 -> -503267.87
A29: Scenario liquidity summary
A30: Metric | B30: Base | C30: Downside | D30: Severe | E30: Management Action
A31: Minimum Cash | B31: =MIN(C14:C26) -> 394703.57 | C31: =MIN(D14:D26) -> 80355.892 | D31: =MIN(E14:E26) -> -253267.87 | E31: =MIN(F14:F26) -> 436800.23
A32: Week 13 Cash | B32: =C26 -> 394703.57 | C32: =D26 -> 80355.892 | D32: =E26 -> -253267.87 | E32: =F26 -> 436800.23
A33: Minimum Headroom | B33: =B31-$B$10 -> 144703.57 | C33: =C31-$B$10 -> -169644.11 | D33: =D31-$B$10 -> -503267.87 | E33: =E31-$B$10 -> 186800.23
A34: Below Policy Weeks | B34: =COUNTIF(C14:C26,"<"&$B$10) -> 0 | C34: =COUNTIF(D14:D26,"<"&$B$10) -> 3 | D34: =COUNTIF(E14:E26,"<"&$B$10) -> 10 | E34: =COUNTIF(F14:F26,"<"&$B$10) -> 0

Sheet CFO Commentary
A1: CFO Month-End Commentary — September 2026
A3: Formula-driven narrative linked to the final management layer.
A5: Executive performance
A6: ="YTD revenue is £"&TEXT('Source Inputs'!B7,"#,##0")&", £"&TEXT('Variance Investigation'!D6,"#,##0")&" ahead of budget. Gross profit is £"&TEXT('Variance Investigation'!D7,"#,##0")&" favourable, but EBITDA is £"&TEXT(ABS('Variance Investigation'!D15),"#,##0")&" below plan, leaving YTD PBT at £"&TEXT('Source Inputs'!B27,"#,##0")&"." -> YTD revenue is £8,300,000, £70,000 ahead of budget. Gross profit is £37,875 favourable, but EBITDA is £35,490 below plan, leaving YTD PBT at £-197,100.
A10: Cost & variance drivers
A11: ="The principal controllable adverse variances are salaries (£"&TEXT('Variance Investigation'!D9,"#,##0")&") and marketing (£"&TEXT('Variance Investigation'!D10,"#,##0")&"). These lines more than offset the gross-profit upside and are the main Q4 cost actions." -> The principal controllable adverse variances are salaries (£43,430) and marketing (£29,221). These lines more than offset the gross-profit upside and are the main Q4 cost actions.
A15: Balance sheet & controls
A16: ="Core controls are clean: balance sheet, bank, AR and AP differences are all effectively zero. "&"The doubtful-debt allowance is £"&TEXT('Source Inputs'!G9,"#,##0")&" versus modelled ECL of £"&TEXT('Source Inputs'!G21,"#,##0")&", so the remaining point is provisioning judgement rather than reconciliation failure." -> Core controls are clean: balance sheet, bank, AR and AP differences are all effectively zero. The doubtful-debt allowance is £35,000 versus modelled ECL of £25,758, so the remaining point is provisioning judgement rather than reconciliation failure.
A20: Working capital
A21: ="September DSO is "&TEXT('Source Inputs'!G26,"0.0")&" days, inventory is "&TEXT('Source Inputs'!G27,"0.0")&" days and DPO is "&TEXT('Source Inputs'!G28,"0.0")&" days, producing a CCC of "&TEXT('Source Inputs'!G29,"0.0")&" days. Management should improve collections and inventory rather than extend suppliers further." -> September DSO is 34.0 days, inventory is 35.8 days and DPO is 88.9 days, producing a CCC of -19.1 days. Management should improve collections and inventory rather than extend suppliers further.
A25: Liquidity
A26: ="The base 13-week forecast retains minimum cash of £"&TEXT('Cash Scenarios'!B31,"#,##0")&". Downside minimum cash falls to £"&TEXT('Cash Scenarios'!C31,"#,##0")&", while the severe case falls to £"&TEXT('Cash Scenarios'!D31,"#,##0")&". The Management Action case preserves £"&TEXT('Cash Scenarios'!E33,"#,##0")&" of minimum headroom through collections, payment scheduling and capex deferral." -> The base 13-week forecast retains minimum cash of £394,704. Downside minimum cash falls to £80,356, while the severe case falls to £-253,268. The Management Action case preserves £186,800 of minimum headroom through collections, payment scheduling and capex deferral.
A30: CFO priorities
A31: Priority | B31: Action | C31: Owner | D31: Timing | E31: Evidence | F31: Status
A32: 1 | B32: Bring salaries and marketing back toward plan | C32: CFO / Commercial Director | D32: Q4 | E32: Variance Investigation | F32: Open
A33: 2 | B33: Execute targeted overdue-AR collection actions | C33: Credit Controller | D33: 30 days | E33: Working Capital Actions | F33: Open
A34: 3 | B34: Reduce inventory days without service disruption | C34: Supply Finance | D34: 60 days | E34: Working Capital Actions | F34: Open
A35: 4 | B35: Document allowance vs ECL provisioning judgement | C35: Finance Manager | D35: Close | E35: BS Reconciliation Pack | F35: Reviewed
A36: 5 | B36: Monitor downside liquidity and defer capex if required | C36: CFO | D36: Weekly | E36: Cash Scenarios | F36: Monitoring

Sheet CFO Management Pack
A1: CFO Management Pack — September 2026
A3: Management accounts | controls | working capital | liquidity | actions
A5: YTD Revenue | D5: YTD EBITDA | G5: EBITDA vs Budget | J5: Final Close Completion
A6: ='Source Inputs'!B7 -> 8300000 | D6: ='Source Inputs'!B25 -> -7599.9369 | G6: ='Variance Investigation'!D15 -> -35489.937 | J6: =100% -> 1
A9: Cash Conversion Cycle | D9: Base Minimum Cash | G9: Base Minimum Headroom | J9: Balance Sheet Check
A10: ='Source Inputs'!G29 -> -19.113094 | D10: ='Cash Scenarios'!B31 -> 394703.57 | G10: ='Cash Scenarios'!B33 -> 144703.57 | J10: ='Source Inputs'!G17 -> 0
A14: Key variance agenda | F14: Cash scenarios
A15: P&L Line | B15: Variance £ | C15: Favourability | D15: Action | F15: Metric | G15: Base | H15: Downside | I15: Severe | J15: Management Action
A16: Revenue | B16: ='Variance Investigation'!D6 -> 70000 | C16: ='Variance Investigation'!F6 -> Favourable | D16: Protect momentum | F16: Minimum Cash | G16: ='Cash Scenarios'!B31 -> 394703.57 | H16: ='Cash Scenarios'!C31 -> 80355.892 | I16: ='Cash Scenarios'!D31 -> -253267.87 | J16: ='Cash Scenarios'!E31 -> 436800.23
A17: Salaries | B17: ='Variance Investigation'!D9 -> 43430.304 | C17: ='Variance Investigation'!F9 -> Adverse | D17: Review people-cost run-rate | F17: Week 13 Cash | G17: ='Cash Scenarios'!B32 -> 394703.57 | H17: ='Cash Scenarios'!C32 -> 80355.892 | I17: ='Cash Scenarios'!D32 -> -253267.87 | J17: ='Cash Scenarios'!E32 -> 436800.23
A18: Marketing | B18: ='Variance Investigation'!D10 -> 29220.634 | C18: ='Variance Investigation'!F10 -> Adverse | D18: Validate ROI / rephase spend | F18: Minimum Headroom | G18: ='Cash Scenarios'!B33 -> 144703.57 | H18: ='Cash Scenarios'!C33 -> -169644.11 | I18: ='Cash Scenarios'!D33 -> -503267.87 | J18: ='Cash Scenarios'!E33 -> 186800.23
A19: Software & IT | B19: ='Variance Investigation'!D13 -> 7200 | C19: ='Variance Investigation'!F13 -> Adverse | D19: Review licences | F19: Below Policy Weeks | G19: ='Cash Scenarios'!B34 -> 0 | H19: ='Cash Scenarios'!C34 -> 3 | I19: ='Cash Scenarios'!D34 -> 10 | J19: ='Cash Scenarios'!E34 -> 0
A20: EBITDA | B20: ='Variance Investigation'!D15 -> -35489.937 | C20: ='Variance Investigation'!F15 -> Adverse | D20: Execute Q4 corrective actions
A23: Financial-control status | F23: Working-capital opportunities
A24: Control | B24: Status | C24: Value | F24: Action | G24: Modelled Cash Effect £ | H24: Priority | I24: Owner
A25: Balance Sheet | B25: PASS | C25: ='Source Inputs'!G17 -> 0 | F25: DSO collection opportunity | G25: ='Working Capital Actions'!B15 -> 68558.333 | H25: High | I25: Credit Controller
A26: Bank Reconciliation | B26: PASS | C26: ='Source Inputs'!G18 -> 0 | F26: Inventory-days opportunity | G26: ='Working Capital Actions'!B16 -> 51592.3 | H26: High | I26: Supply Finance
A27: AR Reconciliation | B27: PASS | C27: ='Source Inputs'!G19 -> 0 | F27: 61+ AR collection scenario | G27: ='Working Capital Actions'!B17 -> 55394.847 | H27: High | I27: Credit Controller
A28: AP Reconciliation | B28: PASS | C28: ='Source Inputs'!G20 -> 2.3283064e-10 | F28: Net opportunity before DPO normalisation | G28: ='Working Capital Actions'!B18 -> 175545.48 | H28: High | I28: Finance Manager
A29: Allowance vs ECL | B29: REVIEW | C29: ='Source Inputs'!G9-'Source Inputs'!G21 -> 9241.835
A32: CFO commentary
A33: ='CFO Commentary'!A6&CHAR(10)&CHAR(10)&'CFO Commentary'!A11&CHAR(10)&CHAR(10)&'CFO Commentary'!A16&CHAR(10)&CHAR(10)&'CFO Commentary'!A21&CHAR(10)&CHAR(10)&'CFO Commentary'!A26 -> YTD revenue is £8,300,000, £70,000 ahead of budget. Gross profit is £37,875 favourable, but EBITDA is £35,490 below plan, leaving YTD PBT at £-197,100. The principal controllable adverse variances are salaries (£43,430) and marketing (£29,221). These lines more than offset the gross-profit upside and are the main Q4 cost actions. Core controls are clean: balance sheet, bank, AR and AP differences are all effectively zero. The doubtful-debt allowance is £35,000 versus modelled ECL of £25,758, so the remaining point is provisioning judgement rather than reconciliation failure. September DSO is 34.0 days, inventory is 35.8 days and DPO is 88.9 days, producing a CCC of -19.1 days. Management should improve collections and inventory rather than extend suppliers further. The base 13-week forecast retains minimum cash of £394,704. Downside minimum cash falls to £80,356, while the severe case falls to £-253,268. The Management Action case preserves £186,800 of minimum headroom through collections, payment scheduling and capex deferral.
A43: CFO action agenda
A44: Priority | B44: Action | C44: Owner | D44: Timing | E44: Evidence | F44: Status
A45: 1 | B45: Control payroll and marketing run-rate | C45: CFO / Commercial Director | D45: Q4 | E45: Variance Investigation | F45: Open
A46: 2 | B46: Accelerate overdue receivables | C46: Credit Controller | D46: 30 days | E46: Working Capital Actions | F46: Open
A47: 3 | B47: Reduce inventory days | C47: Supply Finance | D47: 60 days | E47: Working Capital Actions | F47: Open
A48: 4 | B48: Maintain supplier relationships while managing cash | C48: AP Lead | D48: Weekly | E48: Working Capital Actions | F48: Monitoring
A49: 5 | B49: Trigger capex deferral if downside cash headroom breaches policy | C49: CFO | D49: Weekly | E49: Cash Scenarios | F49: Monitoring

Sheet Portfolio Summary
A1: Project 3 — Recruiter Portfolio Summary
A3: Month-End Management Accounts, Working Capital & 13-Week Cash Forecast | FINAL
A5: Project objective
A6: Built a complete simulated September month-end close from a 940-line double-entry general ledger through adjusted trial balance, management accounts, balance-sheet and subledger reconciliations, working-capital analysis and a 13-week cash forecast. Extended the close into variance investigation, liquidity stress testing and CFO decision support.
A12: Scope | H12: Final control status
A13: GL | B13: 940 double-entry lines | H13: Control | I13: Status | J13: Value
A14: Adjustments | B14: 14 month-end journal lines | H14: Trial Balance | I14: PASS | J14: 0
A15: AR | B15: 60 open invoices | H15: Balance Sheet | I15: PASS | J15: ='Source Inputs'!G17 -> 0
A16: AP | B16: 50 open invoices | H16: Bank Reconciliation | I16: PASS | J16: ='Source Inputs'!G18 -> 0
A17: Reporting | B17: Actual vs Budget management accounts | H17: AR Subledger | I17: PASS | J17: ='Source Inputs'!G19 -> 0
A18: Controls | B18: Bank / AR / AP / balance-sheet reconciliation | H18: AP Subledger | I18: PASS | J18: ='Source Inputs'!G20 -> 2.3283064e-10
A19: Treasury | B19: 4 cash scenarios over 13 weeks | H19: Close Checklist | I19: Complete | J19: 1
A20: Final output | B20: CFO management pack + commentary
A23: Key findings
A24: Revenue | B24: YTD revenue is £70k ahead of budget.
A25: EBITDA | B25: EBITDA is ~£35.5k below budget because salary and marketing overruns absorb the gross-profit upside.
A26: Controls | B26: Balance sheet, bank, AR and AP tie-outs are clean; allowance vs ECL remains a judgemental review.
A27: Working Capital | B27: CCC is ~-19.1 days, but DPO ~88.9 days is high; improve collections/inventory rather than stretch suppliers further.
A28: Liquidity | B28: Base minimum cash is ~£394.7k with ~£144.7k headroom; Downside breaches policy while Management Action restores resilience.
A29: Close | B29: The final simulated close is completed to 100% after review, reconciliation and CFO-pack preparation.
A32: Skills evidenced | H32: Recruiter-safe description
A33: Month-End Close | B33: Accruals, prepayments, depreciation, cut-off and close controls | H33: Independent management-accounting case study for a fictional UK consumer-products company. Built a 940-line double-entry ledger, month-end journals, adjusted trial balance, management accounts, reconciliations, working-capital analysis and a 13-week cash forecast. Added variance investigation, liquidity stress scenarios and CFO commentary. All data and quantified opportunities are synthetic/modelled.
A34: Management Accounting | B34: Actual vs budget reporting and variance investigation
A35: Balance Sheet | B35: Reconciliation pack and control-account review
A36: Working Capital | B36: DSO, DPO, inventory days, ageing and cash actions
A37: Treasury | B37: 13-week cash forecast and stress scenarios
A38: Financial Controls | B38: Balanced TB and bank/AR/AP tie-outs
A39: Business Partnering | B39: CFO commentary, priorities and decision actions
A40: Excel | B40: Formula-driven linked financial model and dashboards
